Workbook

Sheet freq_diagrams
A1: 0,1Hz
A3: G' / gamma | X3: G" / gamma
A37: |Eta*| / gamma | X37: tan δ / gamma
A73: 0,5Hz
A75: G' / gamma | X75: G" / gamma
A109: |Eta*| / gamma | X109: tan δ / gamma
A145: 1Hz
A147: G' / gamma | X147: G" / gamma
A181: |Eta*| / gamma | X181: tan δ / gamma
A217: 5Hz
A219: G' / gamma | X219: G" / gamma
A253: |Eta*| / gamma | X253: tan δ / gamma
A289: 10Hz
A291: G' / gamma | X291: G" / gamma
A325: |Eta*| / gamma | X325: tan δ / gamma
A361: 20Hz
A363: G' / gamma | X363: G" / gamma
A397: |Eta*| / gamma | X397: tan δ / gamma

Sheet input_data
B1: D31_U=0v_30_points
B2: Частота 0,1 Гц | I2: Частота 0,5 Гц | P2: Частота 1 Гц | W2: Частота 5 Гц | AD2: Частота 10 Гц | AK2: Частота 20 Гц
B3: t_seg in s | C3: Tau in Pa | D3: G' in Pa | E3: G" in Pa | F3: |eta*| in Pas | G3: gamma | I3: t_seg in s | J3: Tau in Pa | K3: G' in Pa | L3: G" in Pa | M3: |eta*| in Pas | N3: gamma | P3: t_seg in s | Q3: Tau in Pa | R3: G' in Pa | S3: G" in Pa | T3: |eta*| in Pas | U3: gamma | W3: t_seg in s | X3: Tau in Pa | Y3: G' in Pa | Z3: G" in Pa | AA3: |eta*| in Pas | AB3: gamma | AD3: t_seg in s | AE3: Tau in Pa | AF3: G' in Pa | AG3: G" in Pa | AH3: |eta*| in Pas | AI3: gamma | AK3: t_seg in s | AL3: Tau in Pa | AM3: G' in Pa | AN3: G" in Pa | AO3: |eta*| in Pas | AP3: gamma
A4: 1|1 | H4: 1|1 | O4: 1|1 | V4: 1|1 | AC4: 1|1 | AJ4: 1|1
A5: 1|2 | H5: 1|2 | O5: 1|2 | V5: 1|2 | AC5: 1|2 | AJ5: 1|2
A6: 1|3 | H6: 1|3 | O6: 1|3 | V6: 1|3 | AC6: 1|3 | AJ6: 1|3
A7: 1|4 | H7: 1|4 | O7: 1|4 | V7: 1|4 | AC7: 1|4 | AJ7: 1|4
A8: 1|5 | H8: 1|5 | O8: 1|5 | V8: 1|5 | AC8: 1|5 | AJ8: 1|5
A9: 1|6 | H9: 1|6 | O9: 1|6 | V9: 1|6 | AC9: 1|6 | AJ9: 1|6
A10: 1|7 | H10: 1|7 | O10: 1|7 | V10: 1|7 | AC10: 1|7 | AJ10: 1|7
A11: 1|8 | H11: 1|8 | O11: 1|8 | V11: 1|8 | AC11: 1|8 | AJ11: 1|8
A12: 1|9 | H12: 1|9 | O12: 1|9 | V12: 1|9 | AC12: 1|9 | AJ12: 1|9
A13: 1|10 | H13: 1|10 | O13: 1|10 | V13: 1|10 | AC13: 1|10 | AJ13: 1|10
A14: 1|11 | H14: 1|11 | O14: 1|11 | V14: 1|11 | AC14: 1|11 | AJ14: 1|11
A15: 1|12 | H15: 1|12 | O15: 1|12 | V15: 1|12 | AC15: 1|12 | AJ15: 1|12
... A33: 1|30 | H33: 1|30 | O33: 1|30 | V33: 1|30 | AC33: 1|30 | AJ33: 1|30
B36: D31_U=500v_30_points
B37: Частота 0,1 Гц | I37: Частота 0,5 Гц | P37: Частота 1 Гц | W37: Частота 5 Гц | AD37: Частота 10 Гц | AK37: Частота 20 Гц
B38: t_seg in s | C38: Tau in Pa | D38: G' in Pa | E38: G" in Pa | F38: |eta*| in Pas | G38: gamma | I38: t_seg in s | J38: Tau in Pa | K38: G' in Pa | L38: G" in Pa | M38: |eta*| in Pas | N38: gamma | P38: t_seg in s | Q38: Tau in Pa | R38: G' in Pa | S38: G" in Pa | T38: |eta*| in Pas | U38: gamma | W38: t_seg in s | X38: Tau in Pa | Y38: G' in Pa | Z38: G" in Pa | AA38: |eta*| in Pas | AB38: gamma | AD38: t_seg in s | AE38: Tau in Pa | AF38: G' in Pa | AG38: G" in Pa | AH38: |eta*| in Pas | AI38: gamma | AK38: t_seg in s | AL38: Tau in Pa | AM38: G' in Pa | AN38: G" in Pa | AO38: |eta*| in Pas | AP38: gamma
A39: 1|1 | H39: 1|1 | O39: 1|1 | V39: 1|1 | AC39: 1|1 | AJ39: 1|1
A40: 1|2 | H40: 1|2 | O40: 1|2 | V40: 1|2 | AC40: 1|2 | AJ40: 1|2
A41: 1|3 | H41: 1|3 | O41: 1|3 | V41: 1|3 | AC41: 1|3 | AJ41: 1|3
A42: 1|4 | H42: 1|4 | O42: 1|4 | V42: 1|4 | AC42: 1|4 | AJ42: 1|4
A43: 1|5 | H43: 1|5 | O43: 1|5 | V43: 1|5 | AC43: 1|5 | AJ43: 1|5
A44: 1|6 | H44: 1|6 | O44: 1|6 | V44: 1|6 | AC44: 1|6 | AJ44: 1|6
A45: 1|7 | H45: 1|7 | O45: 1|7 | V45: 1|7 | AC45: 1|7 | AJ45: 1|7
A46: 1|8 | H46: 1|8 | O46: 1|8 | V46: 1|8 | AC46: 1|8 | AJ46: 1|8
A47: 1|9 | H47: 1|9 | O47: 1|9 | V47: 1|9 | AC47: 1|9 | AJ47: 1|9
A48: 1|10 | H48: 1|10 | O48: 1|10 | V48: 1|10 | AC48: 1|10 | AJ48: 1|10
A49: 1|11 | H49: 1|11 | O49: 1|11 | V49: 1|11 | AC49: 1|11 | AJ49: 1|11
A50: 1|12 | H50: 1|12 | O50: 1|12 | V50: 1|12 | AC50: 1|12 | AJ50: 1|12
... A68: 1|30 | H68: 1|30 | O68: 1|30 | V68: 1|30 | AC68: 1|30 | AJ68: 1|30
B70: D31_U=1000v_30_points
B71: Частота 0,1 Гц | I71: Частота 0,5 Гц | P71: Частота 1 Гц | W71: Частота 5 Гц | AD71: Частота 10 Гц | AK71: Частота 20 Гц
B72: t_seg in s | C72: Tau in Pa | D72: G' in Pa | E72: G" in Pa | F72: |eta*| in Pas | G72: gamma | I72: t_seg in s | J72: Tau in Pa | K72: G' in Pa | L72: G" in Pa | M72: |eta*| in Pas | N72: gamma | P72: t_seg in s | Q72: Tau in Pa | R72: G' in Pa | S72: G" in Pa | T72: |eta*| in Pas | U72: gamma | W72: t_seg in s | X72: Tau in Pa | Y72: G' in Pa | Z72: G" in Pa | AA72: |eta*| in Pas | AB72: gamma | AD72: t_seg in s | AE72: Tau in Pa | AF72: G' in Pa | AG72: G" in Pa | AH72: |eta*| in Pas | AI72: gamma | AK72: t_seg in s | AL72: Tau in Pa | AM72: G' in Pa | AN72: G" in Pa | AO72: |eta*| in Pas | AP72: gamma
A73: 1|1 | H73: 1|1 | O73: 1|1 | V73: 1|1 | AC73: 1|1 | AJ73: 1|1
A74: 1|2 | H74: 1|2 | O74: 1|2 | V74: 1|2 | AC74: 1|2 | AJ74: 1|2
A75: 1|3 | H75: 1|3 | O75: 1|3 | V75: 1|3 | AC75: 1|3 | AJ75: 1|3
A76: 1|4 | H76: 1|4 | O76: 1|4 | V76: 1|4 | AC76: 1|4 | AJ76: 1|4
A77: 1|5 | H77: 1|5 | O77: 1|5 | V77: 1|5 | AC77: 1|5 | AJ77: 1|5
...

Sheet output_data
A1: D31
A2: point | B2: f | C2: Gamma_0v | D2: G'_0v | E2: Gamma_500v | F2: G'_500v | G2: Gamma_1000v | H2: G'_1000v | I2: Gamma_1500v | J2: G'_1500v | K2: Gamma_2000v | L2: G'_2000v | M2: Gamma_2500v | N2: G'_2500v | O2: ---------- | P2: Gamma_0v | Q2: G"_0v | R2: Gamma_500v | S2: G"_500v | T2: Gamma_1000v | U2: G"_1000v | V2: Gamma_1500v | W2: G"_1500v | X2: Gamma_2000v | Y2: G"_2000v | Z2: Gamma_2500v | AA2: G"_2500v | AB2: ---------- | AC2: Gamma_0v | AD2: |Eta*|_0v | AE2: Gamma_500v | AF2: |Eta*|_500v | AG2: Gamma_1000v | AH2: |Eta*|_1000v | AI2: Gamma_1500v | AJ2: |Eta*|_1500v | AK2: Gamma_2000v | AL2: |Eta*|_2000v | AM2: Gamma_2500v | AN2: |Eta*|_2500v | AO2: ---------- | AP2: Tau_0v | AQ2: Tau_500v | AR2: Tau_1000v | AS2: Tau_1500v | AT2: Tau_2000v | AU2: Tau_2500v | AV2: ---------- | AW2: G'_0v | AX2: G"_0v | AY2: tan_δ_0v | AZ2: G'_500v | BA2: G"_500v | BB2: tan_δ_500v | BC2: G'_1000v | BD2: G"_1000v | BE2: tan_δ_1000v | BF2: G'_1500v | BG2: G"_1500v | BH2: tan_δ_1500v | BI2: G'_2000v | BJ2: G"_2000v | BK2: tan_δ_2000v | BL2: G'_2500v | BM2: G"_2500v | BN2: tan_δ_2500v | BO2: ---------- | BP2: tan_δ_0v | BQ2: tan_δ_500v | BR2: tan_δ_1000v | BS2: tan_δ_1500v | BT2: tan_δ_2000v | BU2: tan_δ_2500v
B3: Hz | D3: Pa | F3: Pa | H3: Pa | J3: Pa | L3: Pa | N3: Pa | O3: ---------- | Q3: Pa | S3: Pa | U3: Pa | W3: Pa | Y3: Pa | AA3: Pa | AB3: ---------- | AD3: Pas | AF3: Pas | AH3: Pas | AJ3: Pas | AL3: Pas | AN3: Pas | AO3: ---------- | AP3: Pa | AQ3: Pa | AR3: Pa | AS3: Pa | AT3: Pa | AU3: Pa | AV3: ---------- | AW3: Pa | AX3: Pa | AZ3: Pa | BA3: Pa | BC3: Pa | BD3: Pa | BF3: Pa | BG3: Pa | BI3: Pa | BJ3: Pa | BL3: Pa | BM3: Pa | BO3: ----------
C4: D31_0v | D4: D31_0v | E4: D31_500v | F4: D31_500v | G4: D31_1000v | H4: D31_1000v | I4: D31_1500v | J4: D31_1500v | K4: D31_2000v | L4: D31_2000v | M4: D31_2500v | N4: D31_2500v | O4: ---------- | P4: D31_0v | Q4: D31_0v | R4: D31_500v | S4: D31_500v | T4: D31_1000v | U4: D31_1000v | V4: D31_1500v | W4: D31_1500v | X4: D31_2000v | Y4: D31_2000v | Z4: D31_2500v | AA4: D31_2500v | AB4: ---------- | AC4: D31_0v | AD4: D31_0v | AE4: D31_500v | AF4: D31_500v | AG4: D31_1000v | AH4: D31_1000v | AI4: D31_1500v | AJ4: D31_1500v | AK4: D31_2000v | AL4: D31_2000v | AM4: D31_2500v | AN4: D31_2500v | AO4: ---------- | AP4: D31_0v | AQ4: D31_500v | AR4: D31_1000v | AS4: D31_1500v | AT4: D31_2000v | AU4: D31_2500v | AV4: ---------- | AW4: D31_0v | AX4: D31_0v | AY4: D31_0v | AZ4: D31_500v | BA4: D31_500v | BB4: D31_500v | BC4: D31_1000v | BD4: D31_1000v | BE4: D31_1000v | BF4: D31_1500v | BG4: D31_1500v | BH4: D31_1500v | BI4: D31_2000v | BJ4: D31_2000v | BK4: D31_2000v | BL4: D31_2500v | BM4: D31_2500v | BN4: D31_2500v | BO4: ---------- | BP4: D31_0v | BQ4: D31_500v | BR4: D31_1000v | BS4: D31_1500v | BT4: D31_2000v | BU4: D31_2500v
A5: Частота 0,1 Гц
A6: 1 | B6: 0.1 | C6: =IF(input_data!G4="","",input_data!G4) | D6: =IF(input_data!D4="","",input_data!D4) | E6: =IF(input_data!G39="","",input_data!G39) | F6: =IF(input_data!D39="","",input_data!D39) | G6: =IF(input_data!G73="","",input_data!G73) | H6: =IF(input_data!D73="","",input_data!D73) | I6: =IF(input_data!G107="","",input_data!G107) | J6: =IF(input_data!D107="","",input_data!D107) | K6: =IF(input_data!G140="","",input_data!G140) | L6: =IF(input_data!D140="","",input_data!D140) | M6: =IF(input_data!G173="","",input_data!G173) | N6: =IF(input_data!D173="","",input_data!D173) | O6: ---------- | P6: =IF(input_data!G4="","",input_data!G4) | Q6: =IF(input_data!E4="","",input_data!E4) | R6: =IF(input_data!G39="","",input_data!G39) | S6: =IF(input_data!E39="","",input_data!E39) | T6: =IF(input_data!G73="","",input_data!G73) | U6: =IF(input_data!E73="","",input_data!E73) | V6: =IF(input_data!G107="","",input_data!G107) | W6: =IF(input_data!E107="","",input_data!E107) | X6: =IF(input_data!G140="","",input_data!G140) | Y6: =IF(input_data!E140="","",input_data!E140) | Z6: =IF(input_data!G173="","",input_data!G173) | AA6: =IF(input_data!E173="","",input_data!E173) | AB6: ---------- | AC6: =IF(input_data!G4="","",input_data!G4) | AD6: =IF(input_data!F4="","",input_data!F4) | AE6: =IF(input_data!G39="","",input_data!G39) | AF6: =IF(input_data!F39="","",input_data!F39) | AG6: =IF(input_data!G73="","",input_data!G73) | AH6: =IF(input_data!F73="","",input_data!F73) | AI6: =IF(input_data!G107="","",input_data!G107) | AJ6: =IF(input_data!F107="","",input_data!F107) | AK6: =IF(input_data!G140="","",input_data!G140) | AL6: =IF(input_data!F140="","",input_data!F140) | AM6: =IF(input_data!G173="","",input_data!G173) | AN6: =IF(input_data!F173="","",input_data!F173) | AO6: ---------- | AP6: =IF(input_data!C4="","",input_data!C4) | AQ6: =IF(input_data!C39="","",input_data!C39) | AR6: =IF(input_data!C73="","",input_data!C73) | AS6: =IF(input_data!C107="","",input_data!C107) | AT6: =IF(input_data!C140="","",input_data!C140) | AU6: =IF(input_data!C173="","",input_data!C173) | AV6: ---------- | AW6: =IF(input_data!D4="","",input_data!D4) | AX6: =IF(input_data!E4="","",input_data!E4) | AY6: =IFERROR(IF(OR(AW6="",AX6=""),"",AX6/AW6),"") | AZ6: =IF(input_data!D39="","",input_data!D39) | BA6: =IF(input_data!E39="","",input_data!E39) | BB6: =IFERROR(IF(OR(AZ6="",BA6=""),"",BA6/AZ6),"") | BC6: =IF(input_data!D73="","",input_data!D73) | BD6: =IF(input_data!E73="","",input_data!E73) | BE6: =IFERROR(IF(OR(BC6="",BD6=""),"",BD6/BC6),"") | BF6: =IF(input_data!D107="","",input_data!D107) | BG6: =IF(input_data!E107="","",input_data!E107) | BH6: =IFERROR(IF(OR(BF6="",BG6=""),"",BG6/BF6),"") | BI6: =IF(input_data!D140="","",input_data!D140) | BJ6: =IF(input_data!E140="","",input_data!E140) | BK6: =IFERROR(IF(OR(BI6="",BJ6=""),"",BJ6/BI6),"") | BL6: =IF(input_data!D173="","",input_data!D173) | BM6: =IF(input_data!E173="","",input_data!E173) | BN6: =IFERROR(IF(OR(BL6="",BM6=""),"",BM6/BL6),"") | BO6: ---------- | BP6: =IF(AY6="","",AY6) | BQ6: =IF(BB6="","",BB6) | BR6: =IF(BE6="","",BE6) | BS6: =IF(BH6="","",BH6) | BT6: =IF(BK6="","",BK6) | BU6: =IF(BN6="","",BN6)
A7: 2 | B7: 0.1 | C7: =IF(input_data!G5="","",input_data!G5) | D7: =IF(input_data!D5="","",input_data!D5) | E7: =IF(input_data!G40="","",input_data!G40) | F7: =IF(input_data!D40="","",input_data!D40) | G7: =IF(input_data!G74="","",input_data!G74) | H7: =IF(input_data!D74="","",input_data!D74) | I7: =IF(input_data!G108="","",input_data!G108) | J7: =IF(input_data!D108="","",input_data!D108) | K7: =IF(input_data!G141="","",input_data!G141) | L7: =IF(input_data!D141="","",input_data!D141) | M7: =IF(input_data!G174="","",input_data!G174) | N7: =IF(input_data!D174="","",input_data!D174) | O7: ---------- | P7: =IF(input_data!G5="","",input_data!G5) | Q7: =IF(input_data!E5="","",input_data!E5) | R7: =IF(input_data!G40="","",input_data!G40) | S7: =IF(input_data!E40="","",input_data!E40) | T7: =IF(input_data!G74="","",input_data!G74) | U7: =IF(input_data!E74="","",input_data!E74) | V7: =IF(input_data!G108="","",input_data!G108) | W7: =IF(input_data!E108="","",input_data!E108) | X7: =IF(input_data!G141="","",input_data!G141) | Y7: =IF(input_data!E141="","",input_data!E141) | Z7: =IF(input_data!G174="","",input_data!G174) | AA7: =IF(input_data!E174="","",input_data!E174) | AB7: ---------- | AC7: =IF(input_data!G5="","",input_data!G5) | AD7: =IF(input_data!F5="","",input_data!F5) | AE7: =IF(input_data!G40="","",input_data!G40) | AF7: =IF(input_data!F40="","",input_data!F40) | AG7: =IF(input_data!G74="","",input_data!G74) | AH7: =IF(input_data!F74="","",input_data!F74) | AI7: =IF(input_data!G108="","",input_data!G108) | AJ7: =IF(input_data!F108="","",input_data!F108) | AK7: =IF(input_data!G141="","",input_data!G141) | AL7: =IF(input_data!F141="","",input_data!F141) | AM7: =IF(input_data!G174="","",input_data!G174) | AN7: =IF(input_data!F174="","",input_data!F174) | AO7: ---------- | AP7: =IF(input_data!C5="","",input_data!C5) | AQ7: =IF(input_data!C40="","",input_data!C40) | AR7: =IF(input_data!C74="","",input_data!C74) | AS7: =IF(input_data!C108="","",input_data!C108) | AT7: =IF(input_data!C141="","",input_data!C141) | AU7: =IF(input_data!C174="","",input_data!C174) | AV7: ---------- | AW7: =IF(input_data!D5="","",input_data!D5) | AX7: =IF(input_data!E5="","",input_data!E5) | AY7: =IFERROR(IF(OR(AW7="",AX7=""),"",AX7/AW7),"") | AZ7: =IF(input_data!D40="","",input_data!D40) | BA7: =IF(input_data!E40="","",input_data!E40) | BB7: =IFERROR(IF(OR(AZ7="",BA7=""),"",BA7/AZ7),"") | BC7: =IF(input_data!D74="","",input_data!D74) | BD7: =IF(input_data!E74="","",input_data!E74) | BE7: =IFERROR(IF(OR(BC7="",BD7=""),"",BD7/BC7),"") | BF7: =IF(input_data!D108="","",input_data!D108) | BG7: =IF(input_data!E108="","",input_data!E108) | BH7: =IFERROR(IF(OR(BF7="",BG7=""),"",BG7/BF7),"") | BI7: =IF(input_data!D141="","",input_data!D141) | BJ7: =IF(input_data!E141="","",input_data!E141) | BK7: =IFERROR(IF(OR(BI7="",BJ7=""),"",BJ7/BI7),"") | BL7: =IF(input_data!D174="","",input_data!D174) | BM7: =IF(input_data!E174="","",input_data!E174) | BN7: =IFERROR(IF(OR(BL7="",BM7=""),"",BM7/BL7),"") | BO7: ---------- | BP7: =IF(AY7="","",AY7) | BQ7: =IF(BB7="","",BB7) | BR7: =IF(BE7="","",BE7) | BS7: =IF(BH7="","",BH7) | BT7: =IF(BK7="","",BK7) | BU7: =IF(BN7="","",BN7)
A8: 3 | B8: 0.1 | C8: =IF(input_data!G6="","",input_data!G6) | D8: =IF(input_data!D6="","",input_data!D6) | E8: =IF(input_data!G41="","",input_data!G41) | F8: =IF(input_data!D41="","",input_data!D41) | G8: =IF(input_data!G75="","",input_data!G75) | H8: =IF(input_data!D75="","",input_data!D75) | I8: =IF(input_data!G109="","",input_data!G109) | J8: =IF(input_data!D109="","",input_data!D109) | K8: =IF(input_data!G142="","",input_data!G142) | L8: =IF(input_data!D142="","",input_data!D142) | M8: =IF(input_data!G175="","",input_data!G175) | N8: =IF(input_data!D175="","",input_data!D175) | O8: ---------- | P8: =IF(input_data!G6="","",input_data!G6) | Q8: =IF(input_data!E6="","",input_data!E6) | R8: =IF(input_data!G41="","",input_data!G41) | S8: =IF(input_data!E41="","",input_data!E41) | T8: =IF(input_data!G75="","",input_data!G75) | U8: =IF(input_data!E75="","",input_data!E75) | V8: =IF(input_data!G109="","",input_data!G109) | W8: =IF(input_data!E109="","",input_data!E109) | X8: =IF(input_data!G142="","",input_data!G142) | Y8: =IF(input_data!E142="","",input_data!E142) | Z8: =IF(input_data!G175="","",input_data!G175) | AA8: =IF(input_data!E175="","",input_data!E175) | AB8: ---------- | AC8: =IF(input_data!G6="","",input_data!G6) | AD8: =IF(input_data!F6="","",input_data!F6) | AE8: =IF(input_data!G41="","",input_data!G41) | AF8: =IF(input_data!F41="","",input_data!F41) | AG8: =IF(input_data!G75="","",input_data!G75) | AH8: =IF(input_data!F75="","",input_data!F75) | AI8: =IF(input_data!G109="","",input_data!G109) | AJ8: =IF(input_data!F109="","",input_data!F109) | AK8: =IF(input_data!G142="","",input_data!G142) | AL8: =IF(input_data!F142="","",input_data!F142) | AM8: =IF(input_data!G175="","",input_data!G175) | AN8: =IF(input_data!F175="","",input_data!F175) | AO8: ---------- | AP8: =IF(input_data!C6="","",input_data!C6) | AQ8: =IF(input_data!C41="","",input_data!C41) | AR8: =IF(input_data!C75="","",input_data!C75) | AS8: =IF(input_data!C109="","",input_data!C109) | AT8: =IF(input_data!C142="","",input_data!C142) | AU8: =IF(input_data!C175="","",input_data!C175) | AV8: ---------- | AW8: =IF(input_data!D6="","",input_data!D6) | AX8: =IF(input_data!E6="","",input_data!E6) | AY8: =IFERROR(IF(OR(AW8="",AX8=""),"",AX8/AW8),"") | AZ8: =IF(input_data!D41="","",input_data!D41) | BA8: =IF(input_data!E41="","",input_data!E41) | BB8: =IFERROR(IF(OR(AZ8="",BA8=""),"",BA8/AZ8),"") | BC8: =IF(input_data!D75="","",input_data!D75) | BD8: =IF(input_data!E75="","",input_data!E75) | BE8: =IFERROR(IF(OR(BC8="",BD8=""),"",BD8/BC8),"") | BF8: =IF(input_data!D109="","",input_data!D109) | BG8: =IF(input_data!E109="","",input_data!E109) | BH8: =IFERROR(IF(OR(BF8="",BG8=""),"",BG8/BF8),"") | BI8: =IF(input_data!D142="","",input_data!D142) | BJ8: =IF(input_data!E142="","",input_data!E142) | BK8: =IFERROR(IF(OR(BI8="",BJ8=""),"",BJ8/BI8),"") | BL8: =IF(input_data!D175="","",input_data!D175) | BM8: =IF(input_data!E175="","",input_data!E175) | BN8: =IFERROR(IF(OR(BL8="",BM8=""),"",BM8/BL8),"") | BO8: ---------- | BP8: =IF(AY8="","",AY8) | BQ8: =IF(BB8="","",BB8) | BR8: =IF(BE8="","",BE8) | BS8: =IF(BH8="","",BH8) | BT8: =IF(BK8="","",BK8) | BU8: =IF(BN8="","",BN8)
A9: 4 | B9: 0.1 | C9: =IF(input_data!G7="","",input_data!G7) | D9: =IF(input_data!D7="","",input_data!D7) | E9: =IF(input_data!G42="","",input_data!G42) | F9: =IF(input_data!D42="","",input_data!D42) | G9: =IF(input_data!G76="","",input_data!G76) | H9: =IF(input_data!D76="","",input_data!D76) | I9: =IF(input_data!G110="","",input_data!G110) | J9: =IF(input_data!D110="","",input_data!D110) | K9: =IF(input_data!G143="","",input_data!G143) | L9: =IF(input_data!D143="","",input_data!D143) | M9: =IF(input_data!G176="","",input_data!G176) | N9: =IF(input_data!D176="","",input_data!D176) | O9: ---------- | P9: =IF(input_data!G7="","",input_data!G7) | Q9: =IF(input_data!E7="","",input_data!E7) | R9: =IF(input_data!G42="","",input_data!G42) | S9: =IF(input_data!E42="","",input_data!E42) | T9: =IF(input_data!G76="","",input_data!G76) | U9: =IF(input_data!E76="","",input_data!E76) | V9: =IF(input_data!G110="","",input_data!G110) | W9: =IF(input_data!E110="","",input_data!E110) | X9: =IF(input_data!G143="","",input_data!G143) | Y9: =IF(input_data!E143="","",input_data!E143) | Z9: =IF(input_data!G176="","",input_data!G176) | AA9: =IF(input_data!E176="","",input_data!E176) | AB9: ---------- | AC9: =IF(input_data!G7="","",input_data!G7) | AD9: =IF(input_data!F7="","",input_data!F7) | AE9: =IF(input_data!G42="","",input_data!G42) | AF9: =IF(input_data!F42="","",input_data!F42) | AG9: =IF(input_data!G76="","",input_data!G76) | AH9: =IF(input_data!F76="","",input_data!F76) | AI9: =IF(input_data!G110="","",input_data!G110) | AJ9: =IF(input_data!F110="","",input_data!F110) | AK9: =IF(input_data!G143="","",input_data!G143) | AL9: =IF(input_data!F143="","",input_data!F143) | AM9: =IF(input_data!G176="","",input_data!G176) | AN9: =IF(input_data!F176="","",input_data!F176) | AO9: ---------- | AP9: =IF(input_data!C7="","",input_data!C7) | AQ9: =IF(input_data!C42="","",input_data!C42) | AR9: =IF(input_data!C76="","",input_data!C76) | AS9: =IF(input_data!C110="","",input_data!C110) | AT9: =IF(input_data!C143="","",input_data!C143) | AU9: =IF(input_data!C176="","",input_data!C176) | AV9: ---------- | AW9: =IF(input_data!D7="","",input_data!D7) | AX9: =IF(input_data!E7="","",input_data!E7) | AY9: =IFERROR(IF(OR(AW9="",AX9=""),"",AX9/AW9),"") | AZ9: =IF(input_data!D42="","",input_data!D42) | BA9: =IF(input_data!E42="","",input_data!E42) | BB9: =IFERROR(IF(OR(AZ9="",BA9=""),"",BA9/AZ9),"") | BC9: =IF(input_data!D76="","",input_data!D76) | BD9: =IF(input_data!E76="","",input_data!E76) | BE9: =IFERROR(IF(OR(BC9="",BD9=""),"",BD9/BC9),"") | BF9: =IF(input_data!D110="","",input_data!D110) | BG9: =IF(input_data!E110="","",input_data!E110) | BH9: =IFERROR(IF(OR(BF9="",BG9=""),"",BG9/BF9),"") | BI9: =IF(input_data!D143="","",input_data!D143) | BJ9: =IF(input_data!E143="","",input_data!E143) | BK9: =IFERROR(IF(OR(BI9="",BJ9=""),"",BJ9/BI9),"") | BL9: =IF(input_data!D176="","",input_data!D176) | BM9: =IF(input_data!E176="","",input_data!E176) | BN9: =IFERROR(IF(OR(BL9="",BM9=""),"",BM9/BL9),"") | BO9: ---------- | BP9: =IF(AY9="","",AY9) | BQ9: =IF(BB9="","",BB9) | BR9: =IF(BE9="","",BE9) | BS9: =IF(BH9="","",BH9) | BT9: =IF(BK9="","",BK9) | BU9: =IF(BN9="","",BN9)
A10: 5 | B10: 0.1 | C10: =IF(input_data!G8="","",input_data!G8) | D10: =IF(input_data!D8="","",input_data!D8) | E10: =IF(input_data!G43="","",input_data!G43) | F10: =IF(input_data!D43="","",input_data!D43) | G10: =IF(input_data!G77="","",input_data!G77) | H10: =IF(input_data!D77="","",input_data!D77) | I10: =IF(input_data!G111="","",input_data!G111) | J10: =IF(input_data!D111="","",input_data!D111) | K10: =IF(input_data!G144="","",input_data!G144) | L10: =IF(input_data!D144="","",input_data!D144) | M10: =IF(input_data!G177="","",input_data!G177) | N10: =IF(input_data!D177="","",input_data!D177) | O10: ---------- | P10: =IF(input_data!G8="","",input_data!G8) | Q10: =IF(input_data!E8="","",input_data!E8) | R10: =IF(input_data!G43="","",input_data!G43) | S10: =IF(input_data!E43="","",input_data!E43) | T10: =IF(input_data!G77="","",input_data!G77) | U10: =IF(input_data!E77="","",input_data!E77) | V10: =IF(input_data!G111="","",input_data!G111) | W10: =IF(input_data!E111="","",input_data!E111) | X10: =IF(input_data!G144="","",input_data!G144) | Y10: =IF(input_data!E144="","",input_data!E144) | Z10: =IF(input_data!G177="","",input_data!G177) | AA10: =IF(input_data!E177="","",input_data!E177) | AB10: ---------- | AC10: =IF(input_data!G8="","",input_data!G8) | AD10: =IF(input_data!F8="","",input_data!F8) | AE10: =IF(input_data!G43="","",input_data!G43) | AF10: =IF(input_data!F43="","",input_data!F43) | AG10: =IF(input_data!G77="","",input_data!G77) | AH10: =IF(input_data!F77="","",input_data!F77) | AI10: =IF(input_data!G111="","",input_data!G111) | AJ10: =IF(input_data!F111="","",input_data!F111) | AK10: =IF(input_data!G144="","",input_data!G144) | AL10: =IF(input_data!F144="","",input_data!F144) | AM10: =IF(input_data!G177="","",input_data!G177) | AN10: =IF(input_data!F177="","",input_data!F177) | AO10: ---------- | AP10: =IF(input_data!C8="","",input_data!C8) | AQ10: =IF(input_data!C43="","",input_data!C43) | AR10: =IF(input_data!C77="","",input_data!C77) | AS10: =IF(input_data!C111="","",input_data!C111) | AT10: =IF(input_data!C144="","",input_data!C144) | AU10: =IF(input_data!C177="","",input_data!C177) | AV10: ---------- | AW10: =IF(input_data!D8="","",input_data!D8) | AX10: =IF(input_data!E8="","",input_data!E8) | AY10: =IFERROR(IF(OR(AW10="",AX10=""),"",AX10/AW10),"") | AZ10: =IF(input_data!D43="","",input_data!D43) | BA10: =IF(input_data!E43="","",input_data!E43) | BB10: =IFERROR(IF(OR(AZ10="",BA10=""),"",BA10/AZ10),"") | BC10: =IF(input_data!D77="","",input_data!D77) | BD10: =IF(input_data!E77="","",input_data!E77) | BE10: =IFERROR(IF(OR(BC10="",BD10=""),"",BD10/BC10),"") | BF10: =IF(input_data!D111="","",input_data!D111) | BG10: =IF(input_data!E111="","",input_data!E111) | BH10: =IFERROR(IF(OR(BF10="",BG10=""),"",BG10/BF10),"") | BI10: =IF(input_data!D144="","",input_data!D144) | BJ10: =IF(input_data!E144="","",input_data!E144) | BK10: =IFERROR(IF(OR(BI10="",BJ10=""),"",BJ10/BI10),"") | BL10: =IF(input_data!D177="","",input_data!D177) | BM10: =IF(input_data!E177="","",input_data!E177) | BN10: =IFERROR(IF(OR(BL10="",BM10=""),"",BM10/BL10),"") | BO10: ---------- | BP10: =IF(AY10="","",AY10) | BQ10: =IF(BB10="","",BB10) | BR10: =IF(BE10="","",BE10) | BS10: =IF(BH10="","",BH10) | BT10: =IF(BK10="","",BK10) | BU10: =IF(BN10="","",BN10)
A11: 6 | B11: 0.1 | C11: =IF(input_data!G9="","",input_data!G9) | D11: =IF(input_data!D9="","",input_data!D9) | E11: =IF(input_data!G44="","",input_data!G44) | F11: =IF(input_data!D44="","",input_data!D44) | G11: =IF(input_data!G78="","",input_data!G78) | H11: =IF(input_data!D78="","",input_data!D78) | I11: =IF(input_data!G112="","",input_data!G112) | J11: =IF(input_data!D112="","",input_data!D112) | K11: =IF(input_data!G145="","",input_data!G145) | L11: =IF(input_data!D145="","",input_data!D145) | M11: =IF(input_data!G178="","",input_data!G178) | N11: =IF(input_data!D178="","",input_data!D178) | O11: ---------- | P11: =IF(input_data!G9="","",input_data!G9) | Q11: =IF(input_data!E9="","",input_data!E9) | R11: =IF(input_data!G44="","",input_data!G44) | S11: =IF(input_data!E44="","",input_data!E44) | T11: =IF(input_data!G78="","",input_data!G78) | U11: =IF(input_data!E78="","",input_data!E78) | V11: =IF(input_data!G112="","",input_data!G112) | W11: =IF(input_data!E112="","",input_data!E112) | X11: =IF(input_data!G145="","",input_data!G145) | Y11: =IF(input_data!E145="","",input_data!E145) | Z11: =IF(input_data!G178="","",input_data!G178) | AA11: =IF(input_data!E178="","",input_data!E178) | AB11: ---------- | AC11: =IF(input_data!G9="","",input_data!G9) | AD11: =IF(input_data!F9="","",input_data!F9) | AE11: =IF(input_data!G44="","",input_data!G44) | AF11: =IF(input_data!F44="","",input_data!F44) | AG11: =IF(input_data!G78="","",input_data!G78) | AH11: =IF(input_data!F78="","",input_data!F78) | AI11: =IF(input_data!G112="","",input_data!G112) | AJ11: =IF(input_data!F112="","",input_data!F112) | AK11: =IF(input_data!G145="","",input_data!G145) | AL11: =IF(input_data!F145="","",input_data!F145) | AM11: =IF(input_data!G178="","",input_data!G178) | AN11: =IF(input_data!F178="","",input_data!F178) | AO11: ---------- | AP11: =IF(input_data!C9="","",input_data!C9) | AQ11: =IF(input_data!C44="","",input_data!C44) | AR11: =IF(input_data!C78="","",input_data!C78) | AS11: =IF(input_data!C112="","",input_data!C112) | AT11: =IF(input_data!C145="","",input_data!C145) | AU11: =IF(input_data!C178="","",input_data!C178) | AV11: ---------- | AW11: =IF(input_data!D9="","",input_data!D9) | AX11: =IF(input_data!E9="","",input_data!E9) | AY11: =IFERROR(IF(OR(AW11="",AX11=""),"",AX11/AW11),"") | AZ11: =IF(input_data!D44="","",input_data!D44) | BA11: =IF(input_data!E44="","",input_data!E44) | BB11: =IFERROR(IF(OR(AZ11="",BA11=""),"",BA11/AZ11),"") | BC11: =IF(input_data!D78="","",input_data!D78) | BD11: =IF(input_data!E78="","",input_data!E78) | BE11: =IFERROR(IF(OR(BC11="",BD11=""),"",BD11/BC11),"") | BF11: =IF(input_data!D112="","",input_data!D112) | BG11: =IF(input_data!E112="","",input_data!E112) | BH11: =IFERROR(IF(OR(BF11="",BG11=""),"",BG11/BF11),"") | BI11: =IF(input_data!D145="","",input_data!D145) | BJ11: =IF(input_data!E145="","",input_data!E145) | BK11: =IFERROR(IF(OR(BI11="",BJ11=""),"",BJ11/BI11),"") | BL11: =IF(input_data!D178="","",input_data!D178) | BM11: =IF(input_data!E178="","",input_data!E178) | BN11: =IFERROR(IF(OR(BL11="",BM11=""),"",BM11/BL11),"") | BO11: ---------- | BP11: =IF(AY11="","",AY11) | BQ11: =IF(BB11="","",BB11) | BR11: =IF(BE11="","",BE11) | BS11: =IF(BH11="","",BH11) | BT11: =IF(BK11="","",BK11) | BU11: =IF(BN11="","",BN11)
A12: 7 | B12: 0.1 | C12: =IF(input_data!G10="","",input_data!G10) | D12: =IF(input_data!D10="","",input_data!D10) | E12: =IF(input_data!G45="","",input_data!G45) | F12: =IF(input_data!D45="","",input_data!D45) | G12: =IF(input_data!G79="","",input_data!G79) | H12: =IF(input_data!D79="","",input_data!D79) | I12: =IF(input_data!G113="","",input_data!G113) | J12: =IF(input_data!D113="","",input_data!D113) | K12: =IF(input_data!G146="","",input_data!G146) | L12: =IF(input_data!D146="","",input_data!D146) | M12: =IF(input_data!G179="","",input_data!G179) | N12: =IF(input_data!D179="","",input_data!D179) | O12: ---------- | P12: =IF(input_data!G10="","",input_data!G10) | Q12: =IF(input_data!E10="","",input_data!E10) | R12: =IF(input_data!G45="","",input_data!G45) | S12: =IF(input_data!E45="","",input_data!E45) | T12: =IF(input_data!G79="","",input_data!G79) | U12: =IF(input_data!E79="","",input_data!E79) | V12: =IF(input_data!G113="","",input_data!G113) | W12: =IF(input_data!E113="","",input_data!E113) | X12: =IF(input_data!G146="","",input_data!G146) | Y12: =IF(input_data!E146="","",input_data!E146) | Z12: =IF(input_data!G179="","",input_data!G179) | AA12: =IF(input_data!E179="","",input_data!E179) | AB12: ---------- | AC12: =IF(input_data!G10="","",input_data!G10) | AD12: =IF(input_data!F10="","",input_data!F10) | AE12: =IF(input_data!G45="","",input_data!G45) | AF12: =IF(input_data!F45="","",input_data!F45) | AG12: =IF(input_data!G79="","",input_data!G79) | AH12: =IF(input_data!F79="","",input_data!F79) | AI12: =IF(input_data!G113="","",input_data!G113) | AJ12: =IF(input_data!F113="","",input_data!F113) | AK12: =IF(input_data!G146="","",input_data!G146) | AL12: =IF(input_data!F146="","",input_data!F146) | AM12: =IF(input_data!G179="","",input_data!G179) | AN12: =IF(input_data!F179="","",input_data!F179) | AO12: ---------- | AP12: =IF(input_data!C10="","",input_data!C10) | AQ12: =IF(input_data!C45="","",input_data!C45) | AR12: =IF(input_data!C79="","",input_data!C79) | AS12: =IF(input_data!C113="","",input_data!C113) | AT12: =IF(input_data!C146="","",input_data!C146) | AU12: =IF(input_data!C179="","",input_data!C179) | AV12: ---------- | AW12: =IF(input_data!D10="","",input_data!D10) | AX12: =IF(input_data!E10="","",input_data!E10) | AY12: =IFERROR(IF(OR(AW12="",AX12=""),"",AX12/AW12),"") | AZ12: =IF(input_data!D45="","",input_data!D45) | BA12: =IF(input_data!E45="","",input_data!E45) | BB12: =IFERROR(IF(OR(AZ12="",BA12=""),"",BA12/AZ12),"") | BC12: =IF(input_data!D79="","",input_data!D79) | BD12: =IF(input_data!E79="","",input_data!E79) | BE12: =IFERROR(IF(OR(BC12="",BD12=""),"",BD12/BC12),"") | BF12: =IF(input_data!D113="","",input_data!D113) | BG12: =IF(input_data!E113="","",input_data!E113) | BH12: =IFERROR(IF(OR(BF12="",BG12=""),"",BG12/BF12),"") | BI12: =IF(input_data!D146="","",input_data!D146) | BJ12: =IF(input_data!E146="","",input_data!E146) | BK12: =IFERROR(IF(OR(BI12="",BJ12=""),"",BJ12/BI12),"") | BL12: =IF(input_data!D179="","",input_data!D179) | BM12: =IF(input_data!E179="","",input_data!E179) | BN12: =IFERROR(IF(OR(BL12="",BM12=""),"",BM12/BL12),"") | BO12: ---------- | BP12: =IF(AY12="","",AY12) | BQ12: =IF(BB12="","",BB12) | BR12: =IF(BE12="","",BE12) | BS12: =IF(BH12="","",BH12) | BT12: =IF(BK12="","",BK12) | BU12: =IF(BN12="","",BN12)
A13: 8 | B13: 0.1 | C13: =IF(input_data!G11="","",input_data!G11) | D13: =IF(input_data!D11="","",input_data!D11) | E13: =IF(input_data!G46="","",input_data!G46) | F13: =IF(input_data!D46="","",input_data!D46) | G13: =IF(input_data!G80="","",input_data!G80) | H13: =IF(input_data!D80="","",input_data!D80) | I13: =IF(input_data!G114="","",input_data!G114) | J13: =IF(input_data!D114="","",input_data!D114) | K13: =IF(input_data!G147="","",input_data!G147) | L13: =IF(input_data!D147="","",input_data!D147) | M13: =IF(input_data!G180="","",input_data!G180) | N13: =IF(input_data!D180="","",input_data!D180) | O13: ---------- | P13: =IF(input_data!G11="","",input_data!G11) | Q13: =IF(input_data!E11="","",input_data!E11) | R13: =IF(input_data!G46="","",input_data!G46) | S13: =IF(input_data!E46="","",input_data!E46) | T13: =IF(input_data!G80="","",input_data!G80) | U13: =IF(input_data!E80="","",input_data!E80) | V13: =IF(input_data!G114="","",input_data!G114) | W13: =IF(input_data!E114="","",input_data!E114) | X13: =IF(input_data!G147="","",input_data!G147) | Y13: =IF(input_data!E147="","",input_data!E147) | Z13: =IF(input_data!G180="","",input_data!G180) | AA13: =IF(input_data!E180="","",input_data!E180) | AB13: ---------- | AC13: =IF(input_data!G11="","",input_data!G11) | AD13: =IF(input_data!F11="","",input_data!F11) | AE13: =IF(input_data!G46="","",input_data!G46) | AF13: =IF(input_data!F46="","",input_data!F46) | AG13: =IF(input_data!G80="","",input_data!G80) | AH13: =IF(input_data!F80="","",input_data!F80) | AI13: =IF(input_data!G114="","",input_data!G114) | AJ13: =IF(input_data!F114="","",input_data!F114) | AK13: =IF(input_data!G147="","",input_data!G147) | AL13: =IF(input_data!F147="","",input_data!F147) | AM13: =IF(input_data!G180="","",input_data!G180) | AN13: =IF(input_data!F180="","",input_data!F180) | AO13: ---------- | AP13: =IF(input_data!C11="","",input_data!C11) | AQ13: =IF(input_data!C46="","",input_data!C46) | AR13: =IF(input_data!C80="","",input_data!C80) | AS13: =IF(input_data!C114="","",input_data!C114) | AT13: =IF(input_data!C147="","",input_data!C147) | AU13: =IF(input_data!C180="","",input_data!C180) | AV13: ---------- | AW13: =IF(input_data!D11="","",input_data!D11) | AX13: =IF(input_data!E11="","",input_data!E11) | AY13: =IFERROR(IF(OR(AW13="",AX13=""),"",AX13/AW13),"") | AZ13: =IF(input_data!D46="","",input_data!D46) | BA13: =IF(input_data!E46="","",input_data!E46) | BB13: =IFERROR(IF(OR(AZ13="",BA13=""),"",BA13/AZ13),"") | BC13: =IF(input_data!D80="","",input_data!D80) | BD13: =IF(input_data!E80="","",input_data!E80) | BE13: =IFERROR(IF(OR(BC13="",BD13=""),"",BD13/BC13),"") | BF13: =IF(input_data!D114="","",input_data!D114) | BG13: =IF(input_data!E114="","",input_data!E114) | BH13: =IFERROR(IF(OR(BF13="",BG13=""),"",BG13/BF13),"") | BI13: =IF(input_data!D147="","",input_data!D147) | BJ13: =IF(input_data!E147="","",input_data!E147) | BK13: =IFERROR(IF(OR(BI13="",BJ13=""),"",BJ13/BI13),"") | BL13: =IF(input_data!D180="","",input_data!D180) | BM13: =IF(input_data!E180="","",input_data!E180) | BN13: =IFERROR(IF(OR(BL13="",BM13=""),"",BM13/BL13),"") | BO13: ---------- | BP13: =IF(AY13="","",AY13) | BQ13: =IF(BB13="","",BB13) | BR13: =IF(BE13="","",BE13) | BS13: =IF(BH13="","",BH13) | BT13: =IF(BK13="","",BK13) | BU13: =IF(BN13="","",BN13)
A14: 9 | B14: 0.1 | C14: =IF(input_data!G12="","",input_data!G12) | D14: =IF(input_data!D12="","",input_data!D12) | E14: =IF(input_data!G47="","",input_data!G47) | F14: =IF(input_data!D47="","",input_data!D47) | G14: =IF(input_data!G81="","",input_data!G81) | H14: =IF(input_data!D81="","",input_data!D81) | I14: =IF(input_data!G115="","",input_data!G115) | J14: =IF(input_data!D115="","",input_data!D115) | K14: =IF(input_data!G148="","",input_data!G148) | L14: =IF(input_data!D148="","",input_data!D148) | M14: =IF(input_data!G181="","",input_data!G181) | N14: =IF(input_data!D181="","",input_data!D181) | O14: ---------- | P14: =IF(input_data!G12="","",input_data!G12) | Q14: =IF(input_data!E12="","",input_data!E12) | R14: =IF(input_data!G47="","",input_data!G47) | S14: =IF(input_data!E47="","",input_data!E47) | T14: =IF(input_data!G81="","",input_data!G81) | U14: =IF(input_data!E81="","",input_data!E81) | V14: =IF(input_data!G115="","",input_data!G115) | W14: =IF(input_data!E115="","",input_data!E115) | X14: =IF(input_data!G148="","",input_data!G148) | Y14: =IF(input_data!E148="","",input_data!E148) | Z14: =IF(input_data!G181="","",input_data!G181) | AA14: =IF(input_data!E181="","",input_data!E181) | AB14: ---------- | AC14: =IF(input_data!G12="","",input_data!G12) | AD14: =IF(input_data!F12="","",input_data!F12) | AE14: =IF(input_data!G47="","",input_data!G47) | AF14: =IF(input_data!F47="","",input_data!F47) | AG14: =IF(input_data!G81="","",input_data!G81) | AH14: =IF(input_data!F81="","",input_data!F81) | AI14: =IF(input_data!G115="","",input_data!G115) | AJ14: =IF(input_data!F115="","",input_data!F115) | AK14: =IF(input_data!G148="","",input_data!G148) | AL14: =IF(input_data!F148="","",input_data!F148) | AM14: =IF(input_data!G181="","",input_data!G181) | AN14: =IF(input_data!F181="","",input_data!F181) | AO14: ---------- | AP14: =IF(input_data!C12="","",input_data!C12) | AQ14: =IF(input_data!C47="","",input_data!C47) | AR14: =IF(input_data!C81="","",input_data!C81) | AS14: =IF(input_data!C115="","",input_data!C115) | AT14: =IF(input_data!C148="","",input_data!C148) | AU14: =IF(input_data!C181="","",input_data!C181) | AV14: ---------- | AW14: =IF(input_data!D12="","",input_data!D12) | AX14: =IF(input_data!E12="","",input_data!E12) | AY14: =IFERROR(IF(OR(AW14="",AX14=""),"",AX14/AW14),"") | AZ14: =IF(input_data!D47="","",input_data!D47) | BA14: =IF(input_data!E47="","",input_data!E47) | BB14: =IFERROR(IF(OR(AZ14="",BA14=""),"",BA14/AZ14),"") | BC14: =IF(input_data!D81="","",input_data!D81) | BD14: =IF(input_data!E81="","",input_data!E81) | BE14: =IFERROR(IF(OR(BC14="",BD14=""),"",BD14/BC14),"") | BF14: =IF(input_data!D115="","",input_data!D115) | BG14: =IF(input_data!E115="","",input_data!E115) | BH14: =IFERROR(IF(OR(BF14="",BG14=""),"",BG14/BF14),"") | BI14: =IF(input_data!D148="","",input_data!D148) | BJ14: =IF(input_data!E148="","",input_data!E148) | BK14: =IFERROR(IF(OR(BI14="",BJ14=""),"",BJ14/BI14),"") | BL14: =IF(input_data!D181="","",input_data!D181) | BM14: =IF(input_data!E181="","",input_data!E181) | BN14: =IFERROR(IF(OR(BL14="",BM14=""),"",BM14/BL14),"") | BO14: ---------- | BP14: =IF(AY14="","",AY14) | BQ14: =IF(BB14="","",BB14) | BR14: =IF(BE14="","",BE14) | BS14: =IF(BH14="","",BH14) | BT14: =IF(BK14="","",BK14) | BU14: =IF(BN14="","",BN14)
A15: 10 | B15: 0.1 | C15: =IF(input_data!G13="","",input_data!G13) | D15: =IF(input_data!D13="","",input_data!D13) | E15: =IF(input_data!G48="","",input_data!G48) | F15: =IF(input_data!D48="","",input_data!D48) | G15: =IF(input_data!G82="","",input_data!G82) | H15: =IF(input_data!D82="","",input_data!D82) | I15: =IF(input_data!G116="","",input_data!G116) | J15: =IF(input_data!D116="","",input_data!D116) | K15: =IF(input_data!G149="","",input_data!G149) | L15: =IF(input_data!D149="","",input_data!D149) | M15: =IF(input_data!G182="","",input_data!G182) | N15: =IF(input_data!D182="","",input_data!D182) | O15: ---------- | P15: =IF(input_data!G13="","",input_data!G13) | Q15: =IF(input_data!E13="","",input_data!E13) | R15: =IF(input_data!G48="","",input_data!G48) | S15: =IF(input_data!E48="","",input_data!E48) | T15: =IF(input_data!G82="","",input_data!G82) | U15: =IF(input_data!E82="","",input_data!E82) | V15: =IF(input_data!G116="","",input_data!G116) | W15: =IF(input_data!E116="","",input_data!E116) | X15: =IF(input_data!G149="","",input_data!G149) | Y15: =IF(input_data!E149="","",input_data!E149) | Z15: =IF(input_data!G182="","",input_data!G182) | AA15: =IF(input_data!E182="","",input_data!E182) | AB15: ---------- | AC15: =IF(input_data!G13="","",input_data!G13) | AD15: =IF(input_data!F13="","",input_data!F13) | AE15: =IF(input_data!G48="","",input_data!G48) | AF15: =IF(input_data!F48="","",input_data!F48) | AG15: =IF(input_data!G82="","",input_data!G82) | AH15: =IF(input_data!F82="","",input_data!F82) | AI15: =IF(input_data!G116="","",input_data!G116) | AJ15: =IF(input_data!F116="","",input_data!F116) | AK15: =IF(input_data!G149="","",input_data!G149) | AL15: =IF(input_data!F149="","",input_data!F149) | AM15: =IF(input_data!G182="","",input_data!G182) | AN15: =IF(input_data!F182="","",input_data!F182) | AO15: ---------- | AP15: =IF(input_data!C13="","",input_data!C13) | AQ15: =IF(input_data!C48="","",input_data!C48) | AR15: =IF(input_data!C82="","",input_data!C82) | AS15: =IF(input_data!C116="","",input_data!C116) | AT15: =IF(input_data!C149="","",input_data!C149) | AU15: =IF(input_data!C182="","",input_data!C182) | AV15: ---------- | AW15: =IF(input_data!D13="","",input_data!D13) | AX15: =IF(input_data!E13="","",input_data!E13) | AY15: =IFERROR(IF(OR(AW15="",AX15=""),"",AX15/AW15),"") | AZ15: =IF(input_data!D48="","",input_data!D48) | BA15: =IF(input_data!E48="","",input_data!E48) | BB15: =IFERROR(IF(OR(AZ15="",BA15=""),"",BA15/AZ15),"") | BC15: =IF(input_data!D82="","",input_data!D82) | BD15: =IF(input_data!E82="","",input_data!E82) | BE15: =IFERROR(IF(OR(BC15="",BD15=""),"",BD15/BC15),"") | BF15: =IF(input_data!D116="","",input_data!D116) | BG15: =IF(input_data!E116="","",input_data!E116) | BH15: =IFERROR(IF(OR(BF15="",BG15=""),"",BG15/BF15),"") | BI15: =IF(input_data!D149="","",input_data!D149) | BJ15: =IF(input_data!E149="","",input_data!E149) | BK15: =IFERROR(IF(OR(BI15="",BJ15=""),"",BJ15/BI15),"") | BL15: =IF(input_data!D182="","",input_data!D182) | BM15: =IF(input_data!E182="","",input_data!E182) | BN15: =IFERROR(IF(OR(BL15="",BM15=""),"",BM15/BL15),"") | BO15: ---------- | BP15: =IF(AY15="","",AY15) | BQ15: =IF(BB15="","",BB15) | BR15: =IF(BE15="","",BE15) | BS15: =IF(BH15="","",BH15) | BT15: =IF(BK15="","",BK15) | BU15: =IF(BN15="","",BN15)
A16: 11 | B16: 0.1 | C16: =IF(input_data!G14="","",input_data!G14) | D16: =IF(input_data!D14="","",input_data!D14) | E16: =IF(input_data!G49="","",input_data!G49) | F16: =IF(input_data!D49="","",input_data!D49) | G16: =IF(input_data!G83="","",input_data!G83) | H16: =IF(input_data!D83="","",input_data!D83) | I16: =IF(input_data!G117="","",input_data!G117) | J16: =IF(input_data!D117="","",input_data!D117) | K16: =IF(input_data!G150="","",input_data!G150) | L16: =IF(input_data!D150="","",input_data!D150) | M16: =IF(input_data!G183="","",input_data!G183) | N16: =IF(input_data!D183="","",input_data!D183) | O16: ---------- | P16: =IF(input_data!G14="","",input_data!G14) | Q16: =IF(input_data!E14="","",input_data!E14) | R16: =IF(input_data!G49="","",input_data!G49) | S16: =IF(input_data!E49="","",input_data!E49) | T16: =IF(input_data!G83="","",input_data!G83) | U16: =IF(input_data!E83="","",input_data!E83) | V16: =IF(input_data!G117="","",input_data!G117) | W16: =IF(input_data!E117="","",input_data!E117) | X16: =IF(input_data!G150="","",input_data!G150) | Y16: =IF(input_data!E150="","",input_data!E150) | Z16: =IF(input_data!G183="","",input_data!G183) | AA16: =IF(input_data!E183="","",input_data!E183) | AB16: ---------- | AC16: =IF(input_data!G14="","",input_data!G14) | AD16: =IF(input_data!F14="","",input_data!F14) | AE16: =IF(input_data!G49="","",input_data!G49) | AF16: =IF(input_data!F49="","",input_data!F49) | AG16: =IF(input_data!G83="","",input_data!G83) | AH16: =IF(input_data!F83="","",input_data!F83) | AI16: =IF(input_data!G117="","",input_data!G117) | AJ16: =IF(input_data!F117="","",input_data!F117) | AK16: =IF(input_data!G150="","",input_data!G150) | AL16: =IF(input_data!F150="","",input_data!F150) | AM16: =IF(input_data!G183="","",input_data!G183) | AN16: =IF(input_data!F183="","",input_data!F183) | AO16: ---------- | AP16: =IF(input_data!C14="","",input_data!C14) | AQ16: =IF(input_data!C49="","",input_data!C49) | AR16: =IF(input_data!C83="","",input_data!C83) | AS16: =IF(input_data!C117="","",input_data!C117) | AT16: =IF(input_data!C150="","",input_data!C150) | AU16: =IF(input_data!C183="","",input_data!C183) | AV16: ---------- | AW16: =IF(input_data!D14="","",input_data!D14) | AX16: =IF(input_data!E14="","",input_data!E14) | AY16: =IFERROR(IF(OR(AW16="",AX16=""),"",AX16/AW16),"") | AZ16: =IF(input_data!D49="","",input_data!D49) | BA16: =IF(input_data!E49="","",input_data!E49) | BB16: =IFERROR(IF(OR(AZ16="",BA16=""),"",BA16/AZ16),"") | BC16: =IF(input_data!D83="","",input_data!D83) | BD16: =IF(input_data!E83="","",input_data!E83) | BE16: =IFERROR(IF(OR(BC16="",BD16=""),"",BD16/BC16),"") | BF16: =IF(input_data!D117="","",input_data!D117) | BG16: =IF(input_data!E117="","",input_data!E117) | BH16: =IFERROR(IF(OR(BF16="",BG16=""),"",BG16/BF16),"") | BI16: =IF(input_data!D150="","",input_data!D150) | BJ16: =IF(input_data!E150="","",input_data!E150) | BK16: =IFERROR(IF(OR(BI16="",BJ16=""),"",BJ16/BI16),"") | BL16: =IF(input_data!D183="","",input_data!D183) | BM16: =IF(input_data!E183="","",input_data!E183) | BN16: =IFERROR(IF(OR(BL16="",BM16=""),"",BM16/BL16),"") | BO16: ---------- | BP16: =IF(AY16="","",AY16) | BQ16: =IF(BB16="","",BB16) | BR16: =IF(BE16="","",BE16) | BS16: =IF(BH16="","",BH16) | BT16: =IF(BK16="","",BK16) | BU16: =IF(BN16="","",BN16)
A17: 12 | B17: 0.1 | C17: =IF(input_data!G15="","",input_data!G15) | D17: =IF(input_data!D15="","",input_data!D15) | E17: =IF(input_data!G50="","",input_data!G50) | F17: =IF(input_data!D50="","",input_data!D50) | G17: =IF(input_data!G84="","",input_data!G84) | H17: =IF(input_data!D84="","",input_data!D84) | I17: =IF(input_data!G118="","",input_data!G118) | J17: =IF(input_data!D118="","",input_data!D118) | K17: =IF(input_data!G151="","",input_data!G151) | L17: =IF(input_data!D151="","",input_data!D151) | M17: =IF(input_data!G184="","",input_data!G184) | N17: =IF(input_data!D184="","",input_data!D184) | O17: ---------- | P17: =IF(input_data!G15="","",input_data!G15) | Q17: =IF(input_data!E15="","",input_data!E15) | R17: =IF(input_data!G50="","",input_data!G50) | S17: =IF(input_data!E50="","",input_data!E50) | T17: =IF(input_data!G84="","",input_data!G84) | U17: =IF(input_data!E84="","",input_data!E84) | V17: =IF(input_data!G118="","",input_data!G118) | W17: =IF(input_data!E118="","",input_data!E118) | X17: =IF(input_data!G151="","",input_data!G151) | Y17: =IF(input_data!E151="","",input_data!E151) | Z17: =IF(input_data!G184="","",input_data!G184) | AA17: =IF(input_data!E184="","",input_data!E184) | AB17: ---------- | AC17: =IF(input_data!G15="","",input_data!G15) | AD17: =IF(input_data!F15="","",input_data!F15) | AE17: =IF(input_data!G50="","",input_data!G50) | AF17: =IF(input_data!F50="","",input_data!F50) | AG17: =IF(input_data!G84="","",input_data!G84) | AH17: =IF(input_data!F84="","",input_data!F84) | AI17: =IF(input_data!G118="","",input_data!G118) | AJ17: =IF(input_data!F118="","",input_data!F118) | AK17: =IF(input_data!G151="","",input_data!G151) | AL17: =IF(input_data!F151="","",input_data!F151) | AM17: =IF(input_data!G184="","",input_data!G184) | AN17: =IF(input_data!F184="","",input_data!F184) | AO17: ---------- | AP17: =IF(input_data!C15="","",input_data!C15) | AQ17: =IF(input_data!C50="","",input_data!C50) | AR17: =IF(input_data!C84="","",input_data!C84) | AS17: =IF(input_data!C118="","",input_data!C118) | AT17: =IF(input_data!C151="","",input_data!C151) | AU17: =IF(input_data!C184="","",input_data!C184) | AV17: ---------- | AW17: =IF(input_data!D15="","",input_data!D15) | AX17: =IF(input_data!E15="","",input_data!E15) | AY17: =IFERROR(IF(OR(AW17="",AX17=""),"",AX17/AW17),"") | AZ17: =IF(input_data!D50="","",input_data!D50) | BA17: =IF(input_data!E50="","",input_data!E50) | BB17: =IFERROR(IF(OR(AZ17="",BA17=""),"",BA17/AZ17),"") | BC17: =IF(input_data!D84="","",input_data!D84) | BD17: =IF(input_data!E84="","",input_data!E84) | BE17: =IFERROR(IF(OR(BC17="",BD17=""),"",BD17/BC17),"") | BF17: =IF(input_data!D118="","",input_data!D118) | BG17: =IF(input_data!E118="","",input_data!E118) | BH17: =IFERROR(IF(OR(BF17="",BG17=""),"",BG17/BF17),"") | BI17: =IF(input_data!D151="","",input_data!D151) | BJ17: =IF(input_data!E151="","",input_data!E151) | BK17: =IFERROR(IF(OR(BI17="",BJ17=""),"",BJ17/BI17),"") | BL17: =IF(input_data!D184="","",input_data!D184) | BM17: =IF(input_data!E184="","",input_data!E184) | BN17: =IFERROR(IF(OR(BL17="",BM17=""),"",BM17/BL17),"") | BO17: ---------- | BP17: =IF(AY17="","",AY17) | BQ17: =IF(BB17="","",BB17) | BR17: =IF(BE17="","",BE17) | BS17: =IF(BH17="","",BH17) | BT17: =IF(BK17="","",BK17) | BU17: =IF(BN17="","",BN17)
... A25: 20 | B25: 0.1 | C25: =IF(input_data!G23="","",input_data!G23) | D25: =IF(input_data!D23="","",input_data!D23) | E25: =IF(input_data!G58="","",input_data!G58) | F25: =IF(input_data!D58="","",input_data!D58) | G25: =IF(input_data!G92="","",input_data!G92) | H25: =IF(input_data!D92="","",input_data!D92) | I25: =IF(input_data!G126="","",input_data!G126) | J25: =IF(input_data!D126="","",input_data!D126) | K25: =IF(input_data!G159="","",input_data!G159) | L25: =IF(input_data!D159="","",input_data!D159) | M25: =IF(input_data!G192="","",input_data!G192) | N25: =IF(input_data!D192="","",input_data!D192) | O25: ---------- | P25: =IF(input_data!G23="","",input_data!G23) | Q25: =IF(input_data!E23="","",input_data!E23) | R25: =IF(input_data!G58="","",input_data!G58) | S25: =IF(input_data!E58="","",input_data!E58) | T25: =IF(input_data!G92="","",input_data!G92) | U25: =IF(input_data!E92="","",input_data!E92) | V25: =IF(input_data!G126="","",input_data!G126) | W25: =IF(input_data!E126="","",input_data!E126) | X25: =IF(input_data!G159="","",input_data!G159) | Y25: =IF(input_data!E159="","",input_data!E159) | Z25: =IF(input_data!G192="","",input_data!G192) | AA25: =IF(input_data!E192="","",input_data!E192) | AB25: ---------- | AC25: =IF(input_data!G23="","",input_data!G23) | AD25: =IF(input_data!F23="","",input_data!F23) | AE25: =IF(input_data!G58="","",input_data!G58) | AF25: =IF(input_data!F58="","",input_data!F58) | AG25: =IF(input_data!G92="","",input_data!G92) | AH25: =IF(input_data!F92="","",input_data!F92) | AI25: =IF(input_data!G126="","",input_data!G126) | AJ25: =IF(input_data!F126="","",input_data!F126) | AK25: =IF(input_data!G159="","",input_data!G159) | AL25: =IF(input_data!F159="","",input_data!F159) | AM25: =IF(input_data!G192="","",input_data!G192) | AN25: =IF(input_data!F192="","",input_data!F192) | AO25: ---------- | AP25: =IF(input_data!C23="","",input_data!C23) | AQ25: =IF(input_data!C58="","",input_data!C58) | AR25: =IF(input_data!C92="","",input_data!C92) | AS25: =IF(input_data!C126="","",input_data!C126) | AT25: =IF(input_data!C159="","",input_data!C159) | AU25: =IF(input_data!C192="","",input_data!C192) | AV25: ---------- | AW25: =IF(input_data!D23="","",input_data!D23) | AX25: =IF(input_data!E23="","",input_data!E23) | AY25: =IFERROR(IF(OR(AW25="",AX25=""),"",AX25/AW25),"") | AZ25: =IF(input_data!D58="","",input_data!D58) | BA25: =IF(input_data!E58="","",input_data!E58) | BB25: =IFERROR(IF(OR(AZ25="",BA25=""),"",BA25/AZ25),"") | BC25: =IF(input_data!D92="","",input_data!D92) | BD25: =IF(input_data!E92="","",input_data!E92) | BE25: =IFERROR(IF(OR(BC25="",BD25=""),"",BD25/BC25),"") | BF25: =IF(input_data!D126="","",input_data!D126) | BG25: =IF(input_data!E126="","",input_data!E126) | BH25: =IFERROR(IF(OR(BF25="",BG25=""),"",BG25/BF25),"") | BI25: =IF(input_data!D159="","",input_data!D159) | BJ25: =IF(input_data!E159="","",input_data!E159) | BK25: =IFERROR(IF(OR(BI25="",BJ25=""),"",BJ25/BI25),"") | BL25: =IF(input_data!D192="","",input_data!D192) | BM25: =IF(input_data!E192="","",input_data!E192) | BN25: =IFERROR(IF(OR(BL25="",BM25=""),"",BM25/BL25),"") | BO25: ---------- | BP25: =IF(AY25="","",AY25) | BQ25: =IF(BB25="","",BB25) | BR25: =IF(BE25="","",BE25) | BS25: =IF(BH25="","",BH25) | BT25: =IF(BK25="","",BK25) | BU25: =IF(BN25="","",BN25)
A28: Частота 0,5 Гц
A29: 1 | B29: 0.5 | C29: =IF(input_data!N4="","",input_data!N4) | D29: =IF(input_data!K4="","",input_data!K4) | E29: =IF(input_data!N39="","",input_data!N39) | F29: =IF(input_data!K39="","",input_data!K39) | G29: =IF(input_data!N73="","",input_data!N73) | H29: =IF(input_data!K73="","",input_data!K73) | I29: =IF(input_data!N107="","",input_data!N107) | J29: =IF(input_data!K107="","",input_data!K107) | K29: =IF(input_data!N140="","",input_data!N140) | L29: =IF(input_data!K140="","",input_data!K140) | M29: =IF(input_data!N173="","",input_data!N173) | N29: =IF(input_data!K173="","",input_data!K173) | O29: ---------- | P29: =IF(input_data!N4="","",input_data!N4) | Q29: =IF(input_data!L4="","",input_data!L4) | R29: =IF(input_data!N39="","",input_data!N39) | S29: =IF(input_data!L39="","",input_data!L39) | T29: =IF(input_data!N73="","",input_data!N73) | U29: =IF(input_data!L73="","",input_data!L73) | V29: =IF(input_data!N107="","",input_data!N107) | W29: =IF(input_data!L107="","",input_data!L107) | X29: =IF(input_data!N140="","",input_data!N140) | Y29: =IF(input_data!L140="","",input_data!L140) | Z29: =IF(input_data!N173="","",input_data!N173) | AA29: =IF(input_data!L173="","",input_data!L173) | AB29: ---------- | AC29: =IF(input_data!N4="","",input_data!N4) | AD29: =IF(input_data!M4="","",input_data!M4) | AE29: =IF(input_data!N39="","",input_data!N39) | AF29: =IF(input_data!M39="","",input_data!M39) | AG29: =IF(input_data!N73="","",input_data!N73) | AH29: =IF(input_data!M73="","",input_data!M73) | AI29: =IF(input_data!N107="","",input_data!N107) | AJ29: =IF(input_data!M107="","",input_data!M107) | AK29: =IF(input_data!N140="","",input_data!N140) | AL29: =IF(input_data!M140="","",input_data!M140) | AM29: =IF(input_data!N173="","",input_data!N173) | AN29: =IF(input_data!M173="","",input_data!M173) | AO29: ---------- | AP29: =IF(input_data!J4="","",input_data!J4) | AQ29: =IF(input_data!J39="","",input_data!J39) | AR29: =IF(input_data!J73="","",input_data!J73) | AS29: =IF(input_data!J107="","",input_data!J107) | AT29: =IF(input_data!J140="","",input_data!J140) | AU29: =IF(input_data!J173="","",input_data!J173) | AV29: ---------- | AW29: =IF(input_data!K4="","",input_data!K4) | AX29: =IF(input_data!L4="","",input_data!L4) | AY29: =IFERROR(IF(OR(AW29="",AX29=""),"",AX29/AW29),"") | AZ29: =IF(input_data!K39="","",input_data!K39) | BA29: =IF(input_data!L39="","",input_data!L39) | BB29: =IFERROR(IF(OR(AZ29="",BA29=""),"",BA29/AZ29),"") | BC29: =IF(input_data!K73="","",input_data!K73) | BD29: =IF(input_data!L73="","",input_data!L73) | BE29: =IFERROR(IF(OR(BC29="",BD29=""),"",BD29/BC29),"") | BF29: =IF(input_data!K107="","",input_data!K107) | BG29: =IF(input_data!L107="","",input_data!L107) | BH29: =IFERROR(IF(OR(BF29="",BG29=""),"",BG29/BF29),"") | BI29: =IF(input_data!K140="","",input_data!K140) | BJ29: =IF(input_data!L140="","",input_data!L140) | BK29: =IFERROR(IF(OR(BI29="",BJ29=""),"",BJ29/BI29),"") | BL29: =IF(input_data!K173="","",input_data!K173) | BM29: =IF(input_data!L173="","",input_data!L173) | BN29: =IFERROR(IF(OR(BL29="",BM29=""),"",BM29/BL29),"") | BO29: ---------- | BP29: =IF(AY29="","",AY29) | BQ29: =IF(BB29="","",BB29) | BR29: =IF(BE29="","",BE29) | BS29: =IF(BH29="","",BH29) | BT29: =IF(BK29="","",BK29) | BU29: =IF(BN29="","",BN29)
A30: 2 | B30: 0.5 | C30: =IF(input_data!N5="","",input_data!N5) | D30: =IF(input_data!K5="","",input_data!K5) | E30: =IF(input_data!N40="","",input_data!N40) | F30: =IF(input_data!K40="","",input_data!K40) | G30: =IF(input_data!N74="","",input_data!N74) | H30: =IF(input_data!K74="","",input_data!K74) | I30: =IF(input_data!N108="","",input_data!N108) | J30: =IF(input_data!K108="","",input_data!K108) | K30: =IF(input_data!N141="","",input_data!N141) | L30: =IF(input_data!K141="","",input_data!K141) | M30: =IF(input_data!N174="","",input_data!N174) | N30: =IF(input_data!K174="","",input_data!K174) | O30: ---------- | P30: =IF(input_data!N5="","",input_data!N5) | Q30: =IF(input_data!L5="","",input_data!L5) | R30: =IF(input_data!N40="","",input_data!N40) | S30: =IF(input_data!L40="","",input_data!L40) | T30: =IF(input_data!N74="","",input_data!N74) | U30: =IF(input_data!L74="","",input_data!L74) | V30: =IF(input_data!N108="","",input_data!N108) | W30: =IF(input_data!L108="","",input_data!L108) | X30: =IF(input_data!N141="","",input_data!N141) | Y30: =IF(input_data!L141="","",input_data!L141) | Z30: =IF(input_data!N174="","",input_data!N174) | AA30: =IF(input_data!L174="","",input_data!L174) | AB30: ---------- | AC30: =IF(input_data!N5="","",input_data!N5) | AD30: =IF(input_data!M5="","",input_data!M5) | AE30: =IF(input_data!N40="","",input_data!N40) | AF30: =IF(input_data!M40="","",input_data!M40) | AG30: =IF(input_data!N74="","",input_data!N74) | AH30: =IF(input_data!M74="","",input_data!M74) | AI30: =IF(input_data!N108="","",input_data!N108) | AJ30: =IF(input_data!M108="","",input_data!M108) | AK30: =IF(input_data!N141="","",input_data!N141) | AL30: =IF(input_data!M141="","",input_data!M141) | AM30: =IF(input_data!N174="","",input_data!N174) | AN30: =IF(input_data!M174="","",input_data!M174) | AO30: ---------- | AP30: =IF(input_data!J5="","",input_data!J5) | AQ30: =IF(input_data!J40="","",input_data!J40) | AR30: =IF(input_data!J74="","",input_data!J74) | AS30: =IF(input_data!J108="","",input_data!J108) | AT30: =IF(input_data!J141="","",input_data!J141) | AU30: =IF(input_data!J174="","",input_data!J174) | AV30: ---------- | AW30: =IF(input_data!K5="","",input_data!K5) | AX30: =IF(input_data!L5="","",input_data!L5) | AY30: =IFERROR(IF(OR(AW30="",AX30=""),"",AX30/AW30),"") | AZ30: =IF(input_data!K40="","",input_data!K40) | BA30: =IF(input_data!L40="","",input_data!L40) | BB30: =IFERROR(IF(OR(AZ30="",BA30=""),"",BA30/AZ30),"") | BC30: =IF(input_data!K74="","",input_data!K74) | BD30: =IF(input_data!L74="","",input_data!L74) | BE30: =IFERROR(IF(OR(BC30="",BD30=""),"",BD30/BC30),"") | BF30: =IF(input_data!K108="","",input_data!K108) | BG30: =IF(input_data!L108="","",input_data!L108) | BH30: =IFERROR(IF(OR(BF30="",BG30=""),"",BG30/BF30),"") | BI30: =IF(input_data!K141="","",input_data!K141) | BJ30: =IF(input_data!L141="","",input_data!L141) | BK30: =IFERROR(IF(OR(BI30="",BJ30=""),"",BJ30/BI30),"") | BL30: =IF(input_data!K174="","",input_data!K174) | BM30: =IF(input_data!L174="","",input_data!L174) | BN30: =IFERROR(IF(OR(BL30="",BM30=""),"",BM30/BL30),"") | BO30: ---------- | BP30: =IF(AY30="","",AY30) | BQ30: =IF(BB30="","",BB30) | BR30: =IF(BE30="","",BE30) | BS30: =IF(BH30="","",BH30) | BT30: =IF(BK30="","",BK30) | BU30: =IF(BN30="","",BN30)
