Workbook

Sheet freq_diagrams
A1: 0.1Hz | AW1: 0.1Hz
A82: 0.5Hz | AW82: 0.5Hz
A161: 1.0Hz | AW161: 1.0Hz
A243: 5.0Hz | AW243: 5.0Hz
A326: 10.0Hz | AW326: 10.0Hz
A406: 20.0Hz | AW406: 20.0Hz
A488: 30.0Hz | AW488: 30.0Hz
A571: 50.0Hz | AW571: 50.0Hz
A654: 75.0Hz | AW654: 75.0Hz
A736: 100.0Hz | AW736: 100.0Hz

Sheet input_data
B1: Частотные характеристики при 20°С SCTNA=60p_Katal68=2p_PyrO=40p_U=0v_30_points | BM1: 0v
B2: Частота 0,1 Гц | I2: Частота 0,5 Гц | P2: Частота 1 Гц | W2: Частота 5 Гц | AD2: Частота 10 Гц | AK2: Частота 20 Гц | AR2: Частота 30 Гц | AY2: Частота 50 Гц | BF2: Частота 75 Гц | BM2: Частота 100 Гц
B3: t_seg in s | C3: Tau in Pa | D3: G' in Pa | E3: G" in Pa | F3: |eta*| in Pas | G3: gamma | I3: t_seg in s | J3: Tau in Pa | K3: G' in Pa | L3: G" in Pa | M3: |eta*| in Pas | N3: gamma | P3: t_seg in s | Q3: Tau in Pa | R3: G' in Pa | S3: G" in Pa | T3: |eta*| in Pas | U3: gamma | W3: t_seg in s | X3: Tau in Pa | Y3: G' in Pa | Z3: G" in Pa | AA3: |eta*| in Pas | AB3: gamma | AD3: t_seg in s | AE3: Tau in Pa | AF3: G' in Pa | AG3: G" in Pa | AH3: |eta*| in Pas | AI3: gamma | AK3: t_seg in s | AL3: Tau in Pa | AM3: G' in Pa | AN3: G" in Pa | AO3: |eta*| in Pas | AP3: gamma | AR3: t_seg in s | AS3: Tau in Pa | AT3: G' in Pa | AU3: G" in Pa | AV3: |eta*| in Pas | AW3: gamma | AY3: t_seg in s | AZ3: Tau in Pa | BA3: G' in Pa | BB3: G" in Pa | BC3: |eta*| in Pas | BD3: gamma | BF3: t_seg in s | BG3: Tau in Pa | BH3: G' in Pa | BI3: G" in Pa | BJ3: |eta*| in Pas | BK3: gamma | BM3: t_seg in s | BN3: Tau in Pa | BO3: G' in Pa | BP3: G" in Pa | BQ3: |eta*| in Pas | BR3: gamma
A4: 1|1 | B4: 236.6 | C4: 1466 | D4: 121400 | E4: 34680 | F4: 200900 | G4: 0.01161 | H4: 1|1 | I4: 91.12 | J4: 158.7 | K4: 162700 | L4: 5534 | M4: 51830 | N4: 0.0009749 | O4: 1|1 | P4: 73.71 | Q4: 187.4 | R4: 185100 | S4: 11990 | T4: 29520 | U4: 0.00101 | V4: 1|1 | W4: 48.63 | X4: 176.4 | Y4: 178900 | Z4: 8995 | AA4: 5702 | AB4: 0.000985 | AC4: 1|1 | AD4: 44.4 | AE4: 177.8 | AF4: 179500 | AG4: 4606 | AH4: 2857 | AI4: 0.0009901 | AJ4: 1|1 | AK4: 39.36 | AL4: 177.5 | AM4: 176400 | AN4: 9066 | AO4: 1405 | AP4: 0.001005 | AQ4: 1|1 | AR4: 32.56 | AS4: 183.1 | AT4: 177200 | AU4: 9700 | AV4: 921.2 | AW4: 0.001032 | AX4: 1|1 | AY4: 32.7 | AZ4: 179.5 | BA4: 176000 | BB4: 14740 | BC4: 550.1 | BD4: 0.001016 | BE4: 1|1 | BF4: 32.51 | BG4: 164.7 | BH4: 164700 | BI4: 8650 | BJ4: 350 | BK4: 0.0009984 | BL4: 1|1 | BM4: 30.36 | BN4: 155.1 | BO4: 163500 | BP4: 26080 | BQ4: 263.5 | BR4: 0.0009369 | BT4: 100 | BU4: 20.72
A5: 1|2 | B5: 480.5 | C5: 1704 | D5: 119900 | E5: 35400 | F5: 198900 | G5: 0.01363 | H5: 1|2 | I5: 193.1 | J5: 290.2 | K5: 196200 | L5: 10370 | M5: 62530 | N5: 0.001477 | O5: 1|2 | P5: 160.7 | Q5: 251.8 | R5: 168800 | S5: 8619 | T5: 26900 | U5: 0.00149 | V5: 1|2 | W5: 103.8 | X5: 289.1 | Y5: 194200 | Z5: 9992 | AA5: 6190 | AB5: 0.001487 | AC5: 1|2 | AD5: 92.63 | AE5: 285.1 | AF5: 194000 | AG5: 11440 | AH5: 3092 | AI5: 0.001467 | AJ5: 1|2 | AK5: 81.78 | AL5: 255.2 | AM5: 171900 | AN5: 9192 | AO5: 1370 | AP5: 0.001483 | AQ5: 1|2 | AR5: 74.05 | AS5: 266 | AT5: 176000 | AU5: 12430 | AV5: 916 | AW5: 0.001507 | AX5: 1|2 | AY5: 71.76 | AZ5: 255.2 | BA5: 176400 | BB5: 5761 | BC5: 549.6 | BD5: 0.001446 | BE5: 1|2 | BF5: 71.76 | BG5: 237.9 | BH5: 159000 | BI5: 12420 | BJ5: 338.4 | BK5: 0.001492 | BL5: 1|2 | BM5: 68.48 | BN5: 241.7 | BP5: 15330 | BQ5: 24.39 | BR5: 0.00154 | BT5: 100 | BU5: 20.71
A6: 1|3 | B6: 723 | C6: 2062 | D6: 104300 | E6: 36350 | F6: 175900 | G6: 0.01866 | H6: 1|3 | I6: 296.1 | J6: 450 | K6: 203800 | L6: 13420 | M6: 65020 | N6: 0.002203 | O6: 1|3 | P6: 245.5 | Q6: 360.6 | R6: 162400 | S6: 8981 | T6: 25890 | U6: 0.002217 | V6: 1|3 | W6: 159 | X6: 426.3 | Y6: 192900 | Z6: 11200 | AA6: 6149 | AB6: 0.002206 | AC6: 1|3 | AD6: 140.7 | AE6: 428.2 | AF6: 191900 | AG6: 10010 | AH6: 3059 | AI6: 0.002228 | AJ6: 1|3 | AK6: 123.4 | AL6: 371.2 | AM6: 168200 | AN6: 8545 | AO6: 1340 | AP6: 0.002204 | AQ6: 1|3 | AR6: 115.3 | AS6: 385.5 | AT6: 171400 | AU6: 9496 | AV6: 891.2 | AW6: 0.002245 | AX6: 1|3 | AY6: 111.1 | AZ6: 383.8 | BA6: 168100 | BB6: 9548 | BC6: 524.5 | BD6: 0.002279 | BE6: 1|3 | BF6: 109.9 | BG6: 356.9 | BH6: 162100 | BI6: 14930 | BJ6: 345.5 | BK6: 0.002192 | BL6: 1|3 | BM6: 106.8 | BN6: 323.3 | BO6: 149100 | BP6: 15280 | BQ6: 238.6 | BR6: 0.002156 | BT6: 100 | BU6: 20.72
A7: 1|4 | B7: 965.6 | C7: 2415 | D7: 89100 | E7: 36010 | F7: 152900 | G7: 0.02513 | H7: 1|4 | I7: 397.9 | J7: 652.8 | K7: 198100 | L7: 18040 | M7: 63330 | N7: 0.003281 | O7: 1|4 | P7: 332.5 | Q7: 524.5 | R7: 159100 | S7: 10580 | T7: 25380 | U7: 0.003289 | V7: 1|4 | W7: 214.1 | X7: 628.8 | Y7: 190500 | Z7: 13070 | AA7: 6079 | AB7: 0.003292 | AC7: 1|4 | AD7: 187.7 | AE7: 595.9 | AF7: 180700 | AG7: 10630 | AH7: 2881 | AI7: 0.003292 | AJ7: 1|4 | AK7: 166 | AL7: 544.4 | AM7: 166800 | AN7: 10230 | AO7: 1330 | AP7: 0.003257 | AQ7: 1|4 | AR7: 156 | AS7: 555.8 | AT7: 168500 | AU7: 10670 | AV7: 876.5 | AW7: 0.003292 | AX7: 1|4 | AY7: 150.9 | AZ7: 537.3 | BA7: 166700 | BB7: 11010 | BC7: 520.4 | BD7: 0.003216 | BE7: 1|4 | BF7: 148.7 | BG7: 534.4 | BH7: 160600 | BI7: 17300 | BJ7: 342.9 | BK7: 0.003307 | BL7: 1|4 | BM7: 144.9 | BN7: 523.2 | BO7: 154300 | BP7: 13340 | BQ7: 246.6 | BR7: 0.003377 | BT7: 100 | BU7: 20.72
A8: 1|5 | B8: 1209 | C8: 2829 | D8: 74140 | E8: 33790 | F8: 129700 | G8: 0.03473 | H8: 1|5 | I8: 500.5 | J8: 883.9 | K8: 180000 | L8: 23700 | M8: 57800 | N8: 0.004868 | O8: 1|5 | P8: 419.4 | Q8: 782.5 | R8: 159500 | S8: 15040 | T8: 25490 | U8: 0.004886 | V8: 1|5 | W8: 269.2 | X8: 922 | Y8: 188000 | Z8: 16530 | AA8: 6006 | AB8: 0.004887 | AC8: 1|5 | AD8: 238.2 | AE8: 799.6 | AF8: 162700 | AG8: 10630 | AH8: 2595 | AI8: 0.004905 | AJ8: 1|5 | AK8: 209 | AL8: 820.4 | AM8: 167400 | AN8: 11940 | AO8: 1336 | AP8: 0.004887 | AQ8: 1|5 | AR8: 196.2 | AS8: 826.8 | AT8: 169800 | AU8: 14320 | AV8: 884.7 | AW8: 0.004852 | AX8: 1|5 | AY8: 190.1 | AZ8: 797.5 | BA8: 167700 | BB8: 17900 | BC8: 525.4 | BD8: 0.004728 | BE8: 1|5 | BF8: 188.1 | BG8: 811 | BH8: 163800 | BI8: 16660 | BJ8: 349.4 | BK8: 0.004926 | BL8: 1|5 | BM8: 183.1 | BN8: 744.6 | BO8: 158100 | BP8: 15970 | BQ8: 252.9 | BR8: 0.004687 | BT8: 100 | BU8: 20.72
A9: 1|6 | B9: 1452 | C9: 3277 | D9: 62630 | E9: 31160 | F9: 111300 | G9: 0.04684 | H9: 1|6 | I9: 602.4 | J9: 1189 | K9: 161500 | L9: 32870 | M9: 52460 | N9: 0.007215 | O9: 1|6 | P9: 504.3 | Q9: 1139 | R9: 154800 | S9: 23640 | T9: 24930 | U9: 0.007275 | V9: 1|6 | W9: 324.4 | X9: 1294 | Y9: 176600 | Z9: 22150 | AA9: 5664 | AB9: 0.007269 | AC9: 1|6 | AD9: 284.7 | AE9: 1107 | AF9: 151700 | AG9: 12640 | AH9: 2423 | AI9: 0.00727 | AJ9: 1|6 | AK9: 250.6 | AL9: 1234 | AM9: 169100 | AN9: 15150 | AO9: 1351 | AP9: 0.007272 | AQ9: 1|6 | AR9: 237.2 | AS9: 1225 | AT9: 170400 | AU9: 14200 | AV9: 887.7 | AW9: 0.007163 | AX9: 1|6 | AY9: 229.4 | AZ9: 1193 | BA9: 158700 | BB9: 21110 | BC9: 498.5 | BD9: 0.007452 | BE9: 1|6 | BF9: 226.5 | BG9: 1177 | BH9: 161000 | BI9: 21230 | BJ9: 344.6 | BK9: 0.007248 | BL9: 1|6 | BM9: 222.3 | BN9: 1126 | BO9: 149700 | BP9: 25420 | BQ9: 241.7 | BR9: 0.007416 | BT9: 100 | BU9: 20.72
A10: 1|7 | B10: 1695 | C10: 3821 | D10: 52660 | E10: 28390 | F10: 95210 | G10: 0.06387 | H10: 1|7 | I10: 704.4 | J10: 1487 | K10: 139300 | L10: 38490 | M10: 46000 | N10: 0.01029 | O10: 1|7 | P10: 591.2 | Q10: 1562 | R10: 140800 | S10: 32230 | T10: 22990 | U10: 0.01081 | V10: 1|7 | W10: 379.4 | X10: 1760 | Y10: 160200 | Z10: 28710 | AA10: 5181 | AB10: 0.01081 | AC10: 1|7 | AD10: 332.8 | AE10: 1614 | AF10: 148200 | AG10: 17820 | AH10: 2376 | AI10: 0.01081 | AJ10: 1|7 | AK10: 292.3 | AL10: 1733 | AM10: 158200 | AN10: 17530 | AO10: 1267 | AP10: 0.01088 | AQ10: 1|7 | AR10: 278.7 | AS10: 1737 | AT10: 158200 | AU10: 15720 | AV10: 825.1 | AW10: 0.01093 | AX10: 1|7 | AY10: 268.6 | AZ10: 1664 | BA10: 150200 | BB10: 20940 | BC10: 472.4 | BD10: 0.01097 | BE10: 1|7 | BF10: 265.4 | BG10: 1637 | BH10: 149600 | BI10: 18400 | BJ10: 319.9 | BK10: 0.01086 | BL10: 1|7 | BM10: 260.5 | BN10: 1678 | BP10: 73970 | BQ10: 117.7 | BR10: 0.01518 | BT10: 100 | BU10: 20.71
A11: 1|8 | B11: 1943 | C11: 4481 | D11: 44100 | E11: 26200 | F11: 81650 | G11: 0.08735 | H11: 1|8 | I11: 807.2 | J11: 1894 | K11: 113300 | L11: 39700 | M11: 38230 | N11: 0.01577 | O11: 1|8 | P11: 676 | Q11: 2007 | R11: 120400 | S11: 34670 | T11: 19940 | U11: 0.01603 | V11: 1|8 | W11: 434.6 | X11: 2353 | Y11: 142600 | Z11: 33910 | AA11: 4664 | AB11: 0.01606 | AC11: 1|8 | AD11: 380.7 | AE11: 2296 | AF11: 140800 | AG11: 23960 | AH11: 2273 | AI11: 0.01608 | AJ11: 1|8 | AK11: 335.6 | AL11: 2403 | AM11: 147800 | AN11: 19660 | AO11: 1186 | AP11: 0.01612 | AQ11: 1|8 | AR11: 319.3 | AS11: 2443 | AT11: 149800 | AU11: 19250 | AV11: 783.9 | AW11: 0.01618 | AX11: 1|8 | AY11: 307.9 | AZ11: 2422 | BA11: 149000 | BB11: 25020 | BC11: 470.7 | BD11: 0.01603 | BE11: 1|8 | BF11: 304.8 | BG11: 2390 | BH11: 147000 | BI11: 20710 | BJ11: 315 | BK11: 0.0161 | BL11: 1|8 | BM11: 298.7 | BN11: 2256 | BO11: 128600 | BP11: 21140 | BQ11: 207.4 | BR11: 0.01732 | BT11: 100 | BU11: 20.72
A12: 1|9 | B12: 2191 | C12: 5241 | D12: 36650 | E12: 24630 | F12: 70290 | G12: 0.1187 | H12: 1|9 | I12: 909.8 | J12: 2362 | K12: 94020 | L12: 39050 | M12: 32410 | N12: 0.0232 | O12: 1|9 | P12: 760.9 | Q12: 2627 | R12: 104200 | S12: 35920 | T12: 17540 | U12: 0.02384 | V12: 1|9 | W12: 491.2 | X12: 3200 | Y12: 128600 | Z12: 37210 | AA12: 4261 | AB12: 0.0239 | AC12: 1|9 | AD12: 428.8 | AE12: 3162 | AF12: 129300 | AG12: 28930 | AH12: 2108 | AI12: 0.02387 | AJ12: 1|9 | AK12: 379.2 | AL12: 3438 | AM12: 141500 | AN12: 24470 | AO12: 1142 | AP12: 0.02395 | AQ12: 1|9 | AR12: 353.3 | AS12: 3559 | AT12: 145000 | AU12: 22480 | AV12: 761.9 | AW12: 0.02425 | AX12: 1|9 | AY12: 340.7 | AZ12: 3538 | BA12: 140700 | BB12: 26710 | BC12: 446.2 | BD12: 0.0247 | BE12: 1|9 | BF12: 343.8 | BG12: 3461 | BH12: 141900 | BI12: 23480 | BJ12: 305.3 | BK12: 0.02405 | BL12: 1|9 | BM12: 336.8 | BN12: 2995 | BO12: 92190 | BP12: 24240 | BQ12: 151.7 | BR12: 0.03142 | BT12: 100 | BU12: 20.71
A13: 1|10 | B13: 2433 | C13: 5746 | D13: 31680 | E13: 24140 | F13: 63390 | G13: 0.1443 | H13: 1|10 | I13: 1012 | J13: 2965 | K13: 76280 | L13: 36410 | M13: 26910 | N13: 0.03508 | O13: 1|10 | P13: 845.8 | Q13: 3414 | R13: 89240 | S13: 36730 | T13: 15360 | U13: 0.03538 | V13: 1|10 | W13: 547 | X13: 4365 | Y13: 116400 | Z13: 39520 | AA13: 3913 | AB13: 0.03551 | AC13: 1|10 | AD13: 452.9 | AE13: 3564 | AF13: 125600 | AG13: 30250 | AH13: 2056 | AI13: 0.02759 | AJ13: 1|10 | AK13: 401 | AL13: 3619 | AM13: 140600 | AN13: 24730 | AO13: 1136 | AP13: 0.02536 | AQ13: 1|10 | AR13: 373.4 | AS13: 3647 | AT13: 145400 | AU13: 21690 | AV13: 762.9 | AW13: 0.02481 | AX13: 1|10 | AY13: 360.8 | AZ13: 3687 | BA13: 137200 | BB13: 30460 | BC13: 437.6 | BD13: 0.02624 | BE13: 1|10 | BF13: 364 | BG13: 3742 | BH13: 139900 | BI13: 21550 | BJ13: 300.4 | BK13: 0.02644 | BL13: 1|10 | BM13: 373.1 | BN13: 3397 | BO13: 84330 | BP13: 24460 | BQ13: 139.7 | BR13: 0.03869 | BT13: 100 | BU13: 20.72
A14: 1|11 | B14: 2660 | C14: 8755 | D14: 4258 | E14: 4763 | F14: 10170 | G14: 1.37 | H14: 1|11 | I14: 1115 | J14: 3710 | K14: 63080 | L14: 33430 | M14: 22730 | N14: 0.05197 | O14: 1|11 | P14: 930.5 | Q14: 4381 | R14: 75540 | S14: 37250 | T14: 13410 | U14: 0.05201 | V14: 1|11 | W14: 602.3 | X14: 5926 | Y14: 104400 | Z14: 41780 | AA14: 3579 | AB14: 0.0527 | AC14: 1|11 | AD14: 478.8 | AE14: 3564 | AF14: 125500 | AG14: 30090 | AH14: 2054 | AI14: 0.02761 | AJ14: 1|11 | AK14: 426.8 | AL14: 3619 | AM14: 140500 | AN14: 24880 | AO14: 1135 | AP14: 0.02536 | AQ14: 1|11 | AR14: 397.7 | AS14: 3647 | AT14: 144600 | AU14: 21700 | AV14: 758.8 | AW14: 0.02494 | AX14: 1|11 | AY14: 383.2 | AZ14: 3687 | BA14: 136100 | BB14: 30050 | BC14: 434.1 | BD14: 0.02645 | BE14: 1|11 | BF14: 386.3 | BG14: 3742 | BH14: 139100 | BI14: 26460 | BJ14: 300.5 | BK14: 0.02643 | BL14: 1|11 | BM14: 392.3 | BN14: 3885 | BO14: 94990 | BP14: 2036 | BQ14: 151.2 | BR14: 0.04089 | BT14: 100 | BU14: 20.71
A15: 1|12 | B15: 2804 | C15: 17820 | D15: 703.2 | E15: 4845 | F15: 7792 | G15: 3.64 | H15: 1|12 | I15: 1216 | J15: 4577 | K15: 51670 | L15: 29710 | M15: 18970 | N15: 0.07678 | O15: 1|12 | P15: 1015 | Q15: 5560 | R15: 62970 | S15: 36710 | T15: 11600 | U15: 0.07629 | V15: 1|12 | W15: 658.7 | X15: 7886 | Y15: 91750 | Z15: 42940 | AA15: 3225 | AB15: 0.07784 | AC15: 1|12 | AD15: 506.4 | AE15: 3564 | AF15: 125500 | AG15: 30010 | AH15: 2054 | AI15: 0.02762 | AJ15: 1|12 | AK15: 452 | AL15: 3619 | AM15: 140600 | AN15: 24880 | AO15: 1136 | AP15: 0.02535 | AQ15: 1|12 | AR15: 422.1 | AS15: 3647 | AU15: 23080 | AV15: 119.8 | AW15: 0.02476 | AX15: 1|12 | AY15: 406.4 | AZ15: 3687 | BA15: 136600 | BB15: 30120 | BC15: 435.6 | BD15: 0.02636 | BE15: 1|12 | BF15: 407.5 | BG15: 3742 | BH15: 138600 | BI15: 21480 | BJ15: 297.6 | BK15: 0.02668 | BL15: 1|12 | BM15: 414.7 | BN15: 3885 | BO15: 79720 | BP15: 24490 | BQ15: 132.7 | BR15: 0.04658 | BT15: 100 | BU15: 20.72
A16: 1|13 | B16: 2953 | C16: 17820 | D16: 536.6 | E16: 5092 | F16: 8150 | G16: 3.48 | H16: 1|13 | I16: 1319 | J16: 5807 | K16: 42670 | L16: 27130 | M16: 16090 | N16: 0.1148 | O16: 1|13 | P16: 1100 | Q16: 6451 | R16: 47870 | S16: 30640 | T16: 9046 | U16: 0.1135 | V16: 1|13 | W16: 714.9 | X16: 10050 | Y16: 78820 | Z16: 42170 | AA16: 2845 | AB16: 0.1124 | AC16: 1|13 | AD16: 531.9 | AE16: 3564 | AF16: 125800 | AG16: 29890 | AH16: 2058 | AI16: 0.02756 | AJ16: 1|13 | AK16: 476.8 | AL16: 3619 | AM16: 140600 | AN16: 24790 | AO16: 1136 | AP16: 0.02535 | AQ16: 1|13 | AR16: 446.1 | AS16: 3647 | AT16: 145500 | AU16: 22130 | AV16: 763.7 | AW16: 0.02478 | AX16: 1|13 | AY16: 428.9 | AZ16: 3687 | BB16: 30890 | BC16: 96.2 | BD16: 0.02586 | BE16: 1|13 | BF16: 430.3 | BG16: 3742 | BH16: 138700 | BI16: 22710 | BJ16: 298.3 | BK16: 0.02662 | BL16: 1|13 | BM16: 438.6 | BN16: 3885 | BO16: 79640 | BP16: 22350 | BQ16: 131.7 | BR16: 0.04696 | BT16: 100 | BU16: 20.72
A17: 1|14 | B17: 3097 | C17: 17820 | D17: 475.1 | E17: 5201 | F17: 8313 | G17: 3.412 | H17: 1|14 | I17: 1421 | J17: 7470 | K17: 34890 | L17: 25910 | M17: 13830 | N17: 0.1719 | O17: 1|14 | P17: 1187 | Q17: 8275 | R17: 39000 | S17: 28270 | T17: 7666 | U17: 0.1718 | V17: 1|14 | W17: 770.4 | X17: 12440 | Y17: 67530 | Z17: 40400 | AA17: 2505 | AB17: 0.158 | AC17: 1|14 | AD17: 559.6 | AE17: 3564 | AF17: 126200 | AG17: 29590 | AH17: 2063 | AI17: 0.02749 | AJ17: 1|14 | AK17: 502.9 | AL17: 3619 | AM17: 140600 | AN17: 24710 | AO17: 1136 | AP17: 0.02535 | AQ17: 1|14 | AR17: 469.7 | AS17: 3647 | AT17: 145200 | AU17: 23420 | AV17: 763.3 | AW17: 0.0248 | AX17: 1|14 | AY17: 452.1 | AZ17: 3687 | BA17: 135700 | BB17: 29130 | BC17: 432.4 | BD17: 0.02656 | BE17: 1|14 | BF17: 453.7 | BG17: 3742 | BH17: 138300 | BI17: 22100 | BJ17: 297.2 | BK17: 0.02672 | BL17: 1|14 | BM17: 460.9 | BN17: 3885 | BO17: 79070 | BP17: 21650 | BQ17: 130.5 | BR17: 0.04739 | BT17: 100 | BU17: 20.72
A18: 1|15 | B18: 3242 | C18: 17820 | D18: 455.4 | E18: 5277 | F18: 8430 | G18: 3.364 | H18: 1|15 | I18: 1524 | J18: 9286 | K18: 26550 | L18: 25350 | M18: 11690 | N18: 0.2529 | O18: 1|15 | P18: 1272 | Q18: 10340 | R18: 30090 | S18: 26920 | T18: 6425 | U18: 0.256 | V18: 1|15 | W18: 826.9 | X18: 14720 | Y18: 56860 | Z18: 37640 | AA18: 2171 | AB18: 0.2158 | AC18: 1|15 | AD18: 585.9 | AE18: 3564 | AF18: 126300 | AG18: 29520 | AH18: 2065 | AI18: 0.02747 | AJ18: 1|15 | AK18: 528.4 | AL18: 3619 | AM18: 140500 | AN18: 24860 | AO18: 1136 | AP18: 0.02536 | AQ18: 1|15 | AR18: 494.3 | AS18: 3647 | AT18: 145100 | AU18: 22210 | AV18: 762 | AW18: 0.02484 | AX18: 1|15 | AY18: 475.4 | AZ18: 3687 | BA18: 137200 | BB18: 29870 | BC18: 437.3 | BD18: 0.02626 | BE18: 1|15 | BF18: 476.5 | BG18: 3742 | BH18: 138900 | BI18: 23290 | BJ18: 298.8 | BK18: 0.02658 | BL18: 1|15 | BM18: 483.4 | BN18: 3885 | BO18: 79950 | BP18: 24470 | BQ18: 133.1 | BR18: 0.04646 | BT18: 100 | BU18: 20.72
A19: 1|16 | B19: 3390 | C19: 17820 | D19: 490.5 | E19: 5390 | F19: 8614 | G19: 3.292 | H19: 1|16 | I19: 1627 | J19: 10440 | K19: 20550 | L19: 24940 | M19: 10290 | N19: 0.3232 | O19: 1|16 | P19: 1359 | Q19: 13600 | R19: 23900 | S19: 26290 | T19: 5655 | U19: 0.3829 | V19: 1|16 | W19: 856.6 | X19: 18000 | Y19: 46510 | Z19: 32150 | AA19: 1800 | AB19: 0.3183 | AC19: 1|16 | AD19: 611.4 | AE19: 3564 | AF19: 126400 | AG19: 29470 | AH19: 2066 | AI19: 0.02745 | AJ19: 1|16 | AK19: 554.1 | AL19: 3619 | AM19: 140400 | AN19: 24670 | AO19: 1134 | AP19: 0.02539 | AQ19: 1|16 | AR19: 518.6 | AS19: 3647 | AT19: 144900 | AU19: 21420 | AV19: 760.3 | AW19: 0.0249 | AX19: 1|16 | AY19: 497.8 | AZ19: 3687 | BA19: 137900 | BB19: 28450 | BC19: 438.5 | BD19: 0.02619 | BE19: 1|16 | BF19: 499.7 | BG19: 3742 | BH19: 138600 | BI19: 22340 | BJ19: 297.9 | BK19: 0.02665 | BL19: 1|16 | BM19: 505.6 | BN19: 3885 | BO19: 79140 | BP19: 23420 | BQ19: 131.4 | BR19: 0.04707 | BT19: 100 | BU19: 20.73
A20: 1|17 | B20: 3539 | C20: 17820 | D20: 540 | E20: 5569 | F20: 8904 | G20: 3.185 | H20: 1|17 | I20: 1729 | J20: 14240 | K20: 13760 | L20: 22170 | M20: 8306 | N20: 0.5457 | O20: 1|17 | P20: 1406 | Q20: 18000 | R20: 21150 | S20: 26590 | T20: 5408 | U20: 0.5297 | V20: 1|17 | W20: 886.5 | X20: 18000 | Y20: 46010 | Z20: 31480 | AA20: 1775 | AB20: 0.3228 | AC20: 1|17 | AD20: 639.5 | AE20: 3564 | AF20: 126700 | AG20: 29440 | AH20: 2070 | AI20: 0.0274 | AJ20: 1|17 | AK20: 580.3 | AL20: 3619 | AM20: 140500 | AN20: 24630 | AO20: 1135 | AP20: 0.02537 | AQ20: 1|17 | AR20: 543 | AS20: 3647 | AT20: 145200 | AU20: 22320 | AV20: 762.3 | AW20: 0.02483 | AX20: 1|17 | AY20: 520.9 | AZ20: 3687 | BA20: 136900 | BB20: 29320 | BC20: 436.1 | BD20: 0.02633 | BE20: 1|17 | BF20: 522.1 | BG20: 3742 | BH20: 137900 | BI20: 23190 | BJ20: 296.7 | BK20: 0.02676 | BL20: 1|17 | BM20: 526.9 | BN20: 3885 | BO20: 79480 | BP20: 23150 | BQ20: 131.8 | BR20: 0.04692 | BT20: 100 | BU20: 20.73
A21: 1|18 | B21: 3683 | C21: 17820 | D21: 616.8 | E21: 5783 | F21: 9256 | G21: 3.064 | H21: 1|18 | I21: 1786 | J21: 17820 | K21: 10150 | L21: 20100 | M21: 7168 | N21: 0.7914 | O21: 1|18 | P21: 1454 | Q21: 18000 | R21: 20490 | S21: 26340 | T21: 5312 | U21: 0.5393 | V21: 1|18 | W21: 916.9 | X21: 18000 | Y21: 45200 | Z21: 31080 | AA21: 1746 | AB21: 0.3281 | AC21: 1|18 | AD21: 665.5 | AE21: 3564 | AF21: 126500 | AG21: 29520 | AH21: 2067 | AI21: 0.02744 | AJ21: 1|18 | AK21: 605.6 | AL21: 3619 | AM21: 140700 | AN21: 24740 | AO21: 1137 | AP21: 0.02534 | AQ21: 1|18 | AR21: 567.2 | AS21: 3647 | AT21: 145900 | AU21: 23220 | AV21: 767 | AW21: 0.02468 | AX21: 1|18 | AY21: 543.5 | AZ21: 3687 | BA21: 136800 | BB21: 28980 | BC21: 435.5 | BD21: 0.02637 | BE21: 1|18 | BF21: 544.6 | BG21: 3742 | BH21: 137900 | BI21: 22120 | BJ21: 296.4 | BK21: 0.02679 | BL21: 1|18 | BM21: 549.9 | BN21: 3885 | BO21: 79840 | BP21: 23930 | BQ21: 132.7 | BR21: 0.04661 | BT21: 100 | BU21: 20.72
A22: 1|19 | B22: 3827 | C22: 17820 | D22: 675.9 | E22: 5935 | F22: 9508 | G22: 2.983 | H22: 1|19 | I22: 1844 | J22: 17820 | K22: 9588 | L22: 19720 | M22: 6981 | N22: 0.8126 | O22: 1|19 | P22: 1502 | Q22: 18000 | R22: 21430 | S22: 26710 | T22: 5451 | U22: 0.5255 | V22: 1|19 | W22: 947.3 | X22: 18000 | Y22: 45070 | Z22: 30560 | AA22: 1733 | AB22: 0.3305 | AC22: 1|19 | AD22: 690.9 | AE22: 3564 | AF22: 126500 | AG22: 29330 | AH22: 2067 | AI22: 0.02745 | AJ22: 1|19 | AK22: 631.2 | AL22: 3619 | AM22: 140700 | AN22: 24560 | AO22: 1137 | AP22: 0.02533 | AQ22: 1|19 | AR22: 591.4 | AS22: 3647 | AT22: 144800 | AU22: 21970 | AV22: 760.1 | AW22: 0.0249 | AX22: 1|19 | AY22: 566.8 | AZ22: 3687 | BA22: 134800 | BB22: 30010 | BC22: 430.2 | BD22: 0.02669 | BE22: 1|19 | BF22: 566.9 | BG22: 3742 | BH22: 138300 | BI22: 22400 | BJ22: 297.2 | BK22: 0.02672 | BL22: 1|19 | BM22: 572.3 | BN22: 3885 | BO22: 54610 | BP22: 21260 | BQ22: 93.27 | BR22: 0.06629 | BT22: 100 | BU22: 20.73
A23: 1|20 | B23: 3976 | C23: 17820 | D23: 689.4 | E23: 5978 | F23: 9578 | G23: 2.961 | H23: 1|20 | I23: 1902 | J23: 17820 | K23: 9909 | L23: 20030 | M23: 7112 | N23: 0.7975 | O23: 1|20 | P23: 1550 | Q23: 18000 | R23: 21770 | S23: 26920 | T23: 5511 | U23: 0.5198 | V23: 1|20 | W23: 977.7 | X23: 18000 | Y23: 45550 | Z23: 30310 | AA23: 1742 | AB23: 0.329 | AC23: 1|20 | AD23: 717.5 | AE23: 3564 | AF23: 126800 | AG23: 29360 | AH23: 2071 | AI23: 0.02739 | AJ23: 1|20 | AK23: 656.7 | AL23: 3619 | AM23: 140900 | AN23: 24600 | AO23: 1138 | AP23: 0.02531 | AQ23: 1|20 | AR23: 616.2 | AS23: 3647 | AT23: 145900 | AU23: 22720 | AV23: 766.4 | AW23: 0.0247 | AX23: 1|20 | AY23: 590.3 | AZ23: 3687 | BA23: 137300 | BB23: 31550 | BC23: 438.7 | BD23: 0.02617 | BE23: 1|20 | BF23: 589.8 | BG23: 3742 | BH23: 138700 | BI23: 24060 | BJ23: 298.8 | BK23: 0.02657 | BL23: 1|20 | BM23: 595.6 | BN23: 3885 | BO23: 79150 | BP23: 22250 | BQ23: 130.8 | BR23: 0.04725 | BT23: 100 | BU23: 20.73
A24: 1|21 | B24: 4120 | C24: 17820 | D24: 712.4 | E24: 6078 | F24: 9739 | G24: 2.912 | H24: 1|21 | I24: 1959 | J24: 17820 | K24: 10290 | L24: 20350 | M24: 7259 | N24: 0.7814 | O24: 1|21 | P24: 1597 | Q24: 18000 | R24: 22400 | S24: 27170 | T24: 5605 | U24: 0.5111 | V24: 1|21 | W24: 1008 | X24: 18000 | Y24: 45490 | Z24: 29950 | AA24: 1734 | AB24: 0.3305 | AC24: 1|21 | AD24: 745.5 | AE24: 3564 | AF24: 126800 | AG24: 29370 | AH24: 2071 | AI24: 0.02739 | AJ24: 1|21 | AK24: 682.2 | AL24: 3619 | AM24: 140700 | AN24: 24440 | AO24: 1136 | AP24: 0.02535 | AQ24: 1|21 | AR24: 641 | AS24: 3647 | AT24: 145200 | AU24: 21930 | AV24: 762.3 | AW24: 0.02483 | AX24: 1|21 | AY24: 613.8 | AZ24: 3687 | BA24: 135200 | BB24: 30030 | BC24: 431.4 | BD24: 0.02662 | BE24: 1|21 | BF24: 612.2 | BG24: 3742 | BH24: 138400 | BI24: 22310 | BJ24: 297.6 | BK24: 0.02669 | BL24: 1|21 | BM24: 617.8 | BN24: 3885 | BO24: 53780 | BP24: 21700 | BQ24: 92.3 | BR24: 0.06698 | BT24: 100 | BU24: 20.73
A25: 1|22 | B25: 4264 | C25: 17820 | D25: 729.2 | E25: 6114 | F25: 9799 | G25: 2.894 | H25: 1|22 | I25: 2017 | J25: 17820 | K25: 10540 | L25: 20560 | M25: 7354 | N25: 0.7713 | O25: 1|22 | P25: 1645 | Q25: 18000 | R25: 22880 | S25: 27330 | T25: 5673 | U25: 0.505 | V25: 1|22 | W25: 1039 | X25: 18000 | Y25: 45780 | Z25: 29970 | AA25: 1742 | AB25: 0.3289 | AC25: 1|22 | AD25: 771 | AE25: 3564 | AF25: 126900 | AG25: 29360 | AH25: 2074 | AI25: 0.02735 | AJ25: 1|22 | AK25: 707.6 | AL25: 3619 | AM25: 140500 | AN25: 24520 | AO25: 1135 | AP25: 0.02537 | AQ25: 1|22 | AR25: 664.5 | AS25: 3647 | AT25: 145500 | AU25: 21530 | AV25: 763.4 | AW25: 0.0248 | AX25: 1|22 | AY25: 636.9 | AZ25: 3687 | BA25: 136800 | BB25: 30700 | BC25: 436.5 | BD25: 0.02631 | BE25: 1|22 | BF25: 634.9 | BG25: 3742 | BH25: 137100 | BI25: 21400 | BJ25: 294.4 | BK25: 0.02698 | BL25: 1|22 | BM25: 640.2 | BN25: 3885 | BO25: 54640 | BP25: 22090 | BQ25: 93.8 | BR25: 0.06591 | BT25: 100 | BU25: 20.73
A26: 1|23 | B26: 4408 | C26: 17820 | D26: 730.9 | E26: 6164 | F26: 9880 | G26: 2.871 | H26: 1|23 | I26: 2074 | J26: 17820 | K26: 10820 | L26: 20760 | M26: 7453 | N26: 0.7611 | O26: 1|23 | P26: 1694 | Q26: 18000 | R26: 23190 | S26: 27450 | T26: 5719 | U26: 0.5008 | V26: 1|23 | W26: 1069 | X26: 18000 | Y26: 45790 | Z26: 29670 | AA26: 1737 | AB26: 0.3299 | AC26: 1|23 | AD26: 795.4 | AE26: 3564 | AF26: 127200 | AG26: 29220 | AH26: 2077 | AI26: 0.02731 | AJ26: 1|23 | AK26: 733 | AL26: 3619 | AM26: 140700 | AN26: 24510 | AO26: 1137 | AP26: 0.02533 | AQ26: 1|23 | AR26: 688.9 | AS26: 3647 | AT26: 146200 | AU26: 24350 | AV26: 769.4 | AW26: 0.0246 | AX26: 1|23 | AY26: 660 | AZ26: 3687 | BA26: 135700 | BB26: 28690 | BC26: 432 | BD26: 0.02658 | BE26: 1|23 | BF26: 658.3 | BG26: 3742 | BH26: 137900 | BI26: 23280 | BJ26: 296.7 | BK26: 0.02677 | BL26: 1|23 | BM26: 662.4 | BN26: 3885 | BO26: 80160 | BP26: 22550 | BQ26: 132.5 | BR26: 0.04665 | BT26: 100 | BU26: 20.72
A27: 1|24 | B27: 4557 | C27: 17820 | D27: 750.6 | E27: 6217 | F27: 9967 | G27: 2.846 | H27: 1|24 | I27: 2133 | J27: 17820 | K27: 11050 | L27: 20940 | M27: 7536 | N27: 0.7527 | O27: 1|24 | P27: 1741 | Q27: 18000 | R27: 23460 | S27: 27580 | T27: 5763 | U27: 0.497 | V27: 1|24 | W27: 1098 | X27: 18000 | Y27: 45840 | Z27: 29470 | AA27: 1735 | AB27: 0.3302 | AC27: 1|24 | AD27: 820.3 | AE27: 3564 | AF27: 127000 | AG27: 29160 | AH27: 2075 | AI27: 0.02734 | AJ27: 1|24 | AK27: 758.8 | AL27: 3619 | AM27: 140600 | AN27: 24410 | AO27: 1136 | AP27: 0.02536 | AQ27: 1|24 | AR27: 712.9 | AS27: 3647 | AT27: 144200 | AU27: 22130 | AV27: 757.5 | AW27: 0.02499 | AX27: 1|24 | AY27: 683.2 | AZ27: 3687 | BA27: 136700 | BB27: 31760 | BC27: 437 | BD27: 0.02627 | BE27: 1|24 | BF27: 681.2 | BG27: 3742 | BH27: 137300 | BI27: 20610 | BJ27: 294.7 | BK27: 0.02695 | BL27: 1|24 | BM27: 685.1 | BN27: 3885 | BO27: 53490 | BP27: 23130 | BQ27: 92.76 | BR27: 0.06665 | BT27: 100 | BU27: 20.73
A28: 1|25 | B28: 4706 | C28: 17820 | D28: 785.2 | E28: 6283 | F28: 10080 | G28: 2.814 | H28: 1|25 | I28: 2190 | J28: 17820 | K28: 11300 | L28: 21120 | M28: 7624 | N28: 0.744 | O28: 1|25 | P28: 1789 | Q28: 18000 | R28: 23690 | S28: 27630 | T28: 5792 | U28: 0.4946 | V28: 1|25 | W28: 1128 | X28: 18000 | Y28: 46210 | Z28: 29450 | AA28: 1744 | AB28: 0.3284 | AC28: 1|25 | AD28: 846.3 | AE28: 3564 | AF28: 126800 | AG28: 29180 | AH28: 2071 | AI28: 0.02739 | AJ28: 1|25 | AK28: 783.8 | AL28: 3619 | AM28: 140900 | AN28: 24470 | AO28: 1138 | AP28: 0.02531 | AQ28: 1|25 | AR28: 736.7 | AS28: 3647 | AT28: 145100 | AU28: 22950 | AV28: 762.8 | AW28: 0.02482 | AX28: 1|25 | AY28: 705.6 | AZ28: 3687 | BA28: 137100 | BB28: 28910 | BC28: 436.5 | BD28: 0.02631 | BE28: 1|25 | BF28: 704.6 | BG28: 3742 | BH28: 137700 | BI28: 20690 | BJ28: 295.5 | BK28: 0.02687 | BL28: 1|25 | BM28: 708 | BN28: 3885 | BO28: 81180 | BP28: 24320 | BQ28: 134.9 | BR28: 0.04584 | BT28: 100 | BU28: 20.73
... A30: 1|27 | B30: 4993 | C30: 17820 | D30: 807.5 | E30: 6424 | F30: 10300 | G30: 2.752 | H30: 1|27 | I30: 2304 | J30: 17820 | K30: 11780 | L30: 21500 | M30: 7803 | N30: 0.727 | O30: 1|27 | P30: 1885 | Q30: 18000 | R30: 23970 | S30: 27750 | T30: 5836 | U30: 0.4908 | V30: 1|27 | W30: 1188 | X30: 18000 | Y30: 46070 | Z30: 29130 | AA30: 1735 | AB30: 0.3302 | AC30: 1|27 | AD30: 897 | AE30: 3564 | AF30: 127100 | AG30: 29090 | AH30: 2076 | AI30: 0.02733 | AJ30: 1|27 | AK30: 834.7 | AL30: 3619 | AM30: 140800 | AN30: 24530 | AO30: 1138 | AP30: 0.02531 | AQ30: 1|27 | AR30: 784.9 | AS30: 3647 | AT30: 144700 | AU30: 21630 | AV30: 759.7 | AW30: 0.02492 | AX30: 1|27 | AY30: 751.5 | AZ30: 3687 | BA30: 133900 | BB30: 28780 | BC30: 426.4 | BD30: 0.02693 | BE30: 1|27 | BF30: 750 | BG30: 3742 | BH30: 137400 | BI30: 20260 | BJ30: 294.6 | BK30: 0.02695 | BL30: 1|27 | BM30: 753.1 | BN30: 3885 | BO30: 79820 | BP30: 21940 | BQ30: 131.8 | BR30: 0.04693 | BT30: 100 | BU30: 20.73
A31: 1|28 | B31: 5138 | C31: 17820 | D31: 822.1 | E31: 6495 | F31: 10420 | G31: 2.722 | H31: 1|28 | I31: 2362 | J31: 17820 | K31: 11950 | L31: 21630 | M31: 7864 | N31: 0.7213 | O31: 1|28 | P31: 1933 | Q31: 18000 | R31: 24340 | S31: 27870 | T31: 5889 | U31: 0.4864 | V31: 1|28 | W31: 1218 | X31: 18000 | Y31: 46140 | Z31: 29060 | AA31: 1736 | AB31: 0.3301 | AC31: 1|28 | AD31: 922.1 | AE31: 3564 | AF31: 127300 | AG31: 29030 | AH31: 2078 | AI31: 0.0273 | AJ31: 1|28 | AK31: 860.3 | AL31: 3619 | AM31: 140700 | AN31: 24360 | AO31: 1137 | AP31: 0.02534 | AQ31: 1|28 | AR31: 808.8 | AS31: 3647 | AT31: 146500 | AU31: 24410 | AV31: 770.8 | AW31: 0.02456 | AX31: 1|28 | AY31: 774.4 | AZ31: 3687 | BB31: 29970 | BC31: 93.36 | BD31: 0.02675 | BE31: 1|28 | BF31: 773.3 | BG31: 3742 | BH31: 138600 | BI31: 24610 | BJ31: 298.7 | BK31: 0.02659 | BL31: 1|28 | BM31: 775.8 | BN31: 3885 | BO31: 80410 | BP31: 21540 | BQ31: 132.5 | BR31: 0.04667 | BT31: 100 | BU31: 20.72
A32: 1|29 | B32: 5282 | C32: 17820 | D32: 813.9 | E32: 6530 | F32: 10470 | G32: 2.708 | H32: 1|29 | I32: 2419 | J32: 17820 | K32: 12060 | L32: 21700 | M32: 7902 | N32: 0.7178 | O32: 1|29 | P32: 1980 | Q32: 18000 | R32: 24480 | S32: 27910 | T32: 5909 | U32: 0.4848 | V32: 1|29 | W32: 1248 | X32: 18000 | Y32: 46870 | Z32: 29160 | AA32: 1757 | AB32: 0.3261 | AC32: 1|29 | AD32: 949.7 | AE32: 3564 | AF32: 127300 | AG32: 29150 | AH32: 2078 | AI32: 0.02729 | AJ32: 1|29 | AK32: 885.9 | AL32: 3619 | AM32: 140700 | AN32: 24330 | AO32: 1136 | AP32: 0.02535 | AQ32: 1|29 | AR32: 833.5 | AS32: 3647 | AT32: 145500 | AU32: 21090 | AV32: 763.2 | AW32: 0.0248 | AX32: 1|29 | AY32: 797.8 | AZ32: 3687 | BA32: 136200 | BB32: 30140 | BC32: 434.4 | BD32: 0.02643 | BE32: 1|29 | BF32: 795.5 | BG32: 3742 | BH32: 138200 | BI32: 21640 | BJ32: 296.8 | BK32: 0.02676 | BL32: 1|29 | BM32: 798.3 | BN32: 3885 | BO32: 79730 | BP32: 22670 | BQ32: 131.9 | BR32: 0.04687 | BT32: 100 | BU32: 20.72
A33: 1|30 | B33: 5431 | C33: 17820 | D33: 864.3 | E33: 6635 | F33: 10650 | G33: 2.663 | H33: 1|30 | I33: 2476 | J33: 17820 | K33: 12330 | L33: 21880 | M33: 7995 | N33: 0.7095 | O33: 1|30 | P33: 2028 | Q33: 18000 | R33: 24910 | S33: 28080 | T33: 5975 | U33: 0.4794 | V33: 1|30 | W33: 1279 | X33: 18000 | Y33: 46990 | Z33: 29230 | AA33: 1761 | AB33: 0.3253 | AC33: 1|30 | AD33: 976.7 | AE33: 3564 | AF33: 127300 | AG33: 29060 | AH33: 2079 | AI33: 0.02729 | AJ33: 1|30 | AK33: 911.6 | AL33: 3619 | AM33: 140800 | AN33: 24350 | AO33: 1137 | AP33: 0.02533 | AQ33: 1|30 | AR33: 857.5 | AS33: 3647 | AT33: 145100 | AU33: 22430 | AV33: 762.4 | AW33: 0.02483 | AX33: 1|30 | AY33: 820.5 | AZ33: 3687 | BA33: 134600 | BB33: 29860 | BC33: 429.5 | BD33: 0.02673 | BE33: 1|30 | BF33: 818.3 | BG33: 3742 | BH33: 138100 | BI33: 23530 | BJ33: 297.2 | BK33: 0.02672 | BL33: 1|30 | BM33: 821.4 | BN33: 3885 | BO33: 81440 | BP33: 22680 | BQ33: 134.5 | BR33: 0.04595 | BT33: 100 | BU33: 20.73
B36: 20°С SCTNA=60p_Katal68=2p_PyrO=40p_U=500v_30_points | BM36: 500v
B37: Частота 0,1 Гц | I37: Частота 0,5 Гц | P37: Частота 1 Гц | W37: Частота 5 Гц | AD37: Частота 10 Гц | AK37: Частота 20 Гц | AR37: Частота 30 Гц | AY37: Частота 50 Гц | BF37: Частота 75 Гц | BM37: Частота 100 Гц
B38: t_seg in s | C38: Tau in Pa | D38: G' in Pa | E38: G" in Pa | F38: |eta*| in Pas | G38: gamma | I38: t_seg in s | J38: Tau in Pa | K38: G' in Pa | L38: G" in Pa | M38: |eta*| in Pas | N38: gamma | P38: t_seg in s | Q38: Tau in Pa | R38: G' in Pa | S38: G" in Pa | T38: |eta*| in Pas | U38: gamma | W38: t_seg in s | X38: Tau in Pa | Y38: G' in Pa | Z38: G" in Pa | AA38: |eta*| in Pas | AB38: gamma | AD38: t_seg in s | AE38: Tau in Pa | AF38: G' in Pa | AG38: G" in Pa | AH38: |eta*| in Pas | AI38: gamma | AK38: t_seg in s | AL38: Tau in Pa | AM38: G' in Pa | AN38: G" in Pa | AO38: |eta*| in Pas | AP38: gamma | AR38: t_seg in s | AS38: Tau in Pa | AT38: G' in Pa | AU38: G" in Pa | AV38: |eta*| in Pas | AW38: gamma | AY38: t_seg in s | AZ38: Tau in Pa | BA38: G' in Pa | BB38: G" in Pa | BC38: |eta*| in Pas | BD38: gamma | BF38: t_seg in s | BG38: Tau in Pa | BH38: G' in Pa | BI38: G" in Pa | BJ38: |eta*| in Pas | BK38: gamma | BM38: t_seg in s | BN38: Tau in Pa | BO38: G' in Pa | BP38: G" in Pa | BQ38: |eta*| in Pas | BR38: gamma
A39: 1|1 | B39: 225.2 | C39: 121.9 | D39: 118400 | E39: 8430 | F39: 189000 | G39: 0.001026 | H39: 1|1 | I39: 91.07 | J39: 116.3 | K39: 116800 | L39: 5757 | M39: 37240 | N39: 0.0009939 | O39: 1|1 | P39: 75.1 | Q39: 83.91 | R39: 83150 | S39: 4075 | T39: 13250 | U39: 0.001008 | V39: 1|1 | W39: 47.24 | X39: 86.71 | Y39: 86670 | Z39: 3917 | AA39: 2762 | AB39: 0.0009994 | AC39: 1|1 | AD39: 38.97 | AE39: 86 | AF39: 91680 | AG39: 877.4 | AH39: 1459 | AI39: 0.000938 | AJ39: 1|1 | AK39: 33.95 | AL39: 101.1 | AM39: 102900 | AN39: 4911 | AO39: 819.9 | AP39: 0.000981 | AQ39: 1|1 | AR39: 32.62 | AS39: 101.7 | AT39: 106300 | AU39: 5478 | AV39: 552.6 | AW39: 0.0009551 | AX39: 1|1 | AY39: 31.68 | AZ39: 94.61 | BA39: 99750 | BB39: 7897 | BC39: 311.7 | BD39: 0.0009455 | BE39: 1|1 | BF39: 30.31 | BG39: 100.2 | BH39: 98510 | BI39: 12660 | BJ39: 210.8 | BK39: 0.001009 | BL39: 1|1 | BM39: 30.56 | BN39: 68.34 | BO39: 67940 | BP39: 11500 | BQ39: 109.7 | BR39: 0.0009918
A40: 1|2 | B40: 467.8 | C40: 151.6 | D40: 119300 | E40: 8262 | F40: 190300 | G40: 0.001268 | H40: 1|2 | I40: 194 | J40: 148.4 | K40: 116700 | L40: 5895 | M40: 37210 | N40: 0.00127 | O40: 1|2 | P40: 159.9 | Q40: 98.19 | R40: 77070 | S40: 3379 | T40: 12280 | U40: 0.001273 | V40: 1|2 | W40: 103.8 | X40: 114.7 | Y40: 90070 | Z40: 4674 | AA40: 2871 | AB40: 0.001272 | AC40: 1|2 | AD40: 85.07 | AE40: 113.5 | AF40: 89930 | AG40: 5579 | AH40: 1434 | AI40: 0.00126 | AJ40: 1|2 | AK40: 77.24 | AL40: 140.5 | AM40: 103800 | AN40: 5401 | AO40: 827.3 | AP40: 0.001351 | AQ40: 1|2 | AR40: 73.02 | AS40: 129 | AT40: 103100 | AU40: 4739 | AV40: 535.6 | AW40: 0.00125 | AX40: 1|2 | AY40: 70.87 | AZ40: 129.1 | BA40: 101900 | BB40: 6972 | BC40: 318 | BD40: 0.001264 | BE40: 1|2 | BF40: 69.59 | BG40: 123.2 | BH40: 99660 | BI40: 10280 | BJ40: 212.6 | BK40: 0.001229 | BL40: 1|2 | BM40: 70.14 | BN40: 88.49 | BO40: 68380 | BP40: 11960 | BQ40: 110.5 | BR40: 0.001275
A41: 1|3 | B41: 711.2 | C41: 191.4 | D41: 117900 | E41: 6455 | F41: 187900 | G41: 0.001622 | H41: 1|3 | I41: 295.8 | J41: 186.3 | K41: 115800 | L41: 5931 | M41: 36910 | N41: 0.001607 | O41: 1|3 | P41: 244.8 | Q41: 122.1 | R41: 75420 | S41: 3439 | T41: 12020 | U41: 0.001617 | V41: 1|3 | W41: 157.5 | X41: 146.6 | Y41: 90760 | Z41: 4840 | AA41: 2893 | AB41: 0.001613 | AC41: 1|3 | AD41: 132.3 | AE41: 147.1 | AF41: 91970 | AG41: 5290 | AH41: 1466 | AI41: 0.001597 | AJ41: 1|3 | AK41: 119 | AL41: 168.5 | AM41: 101900 | AN41: 9076 | AO41: 814.1 | AP41: 0.001647 | AQ41: 1|3 | AR41: 114.3 | AS41: 166.6 | AT41: 104400 | AU41: 4920 | AV41: 542.6 | AW41: 0.001594 | AX41: 1|3 | AY41: 110.1 | AZ41: 166.8 | BA41: 101500 | BB41: 9626 | BC41: 317.6 | BD41: 0.001636 | BE41: 1|3 | BF41: 108.7 | BG41: 154.4 | BH41: 96630 | BI41: 11450 | BJ41: 206.5 | BK41: 0.001586 | BL41: 1|3 | BM41: 108.1 | BN41: 111.1 | BO41: 67730 | BP41: 11780 | BQ41: 109.4 | BR41: 0.001616
A42: 1|4 | B42: 954 | C42: 241.9 | D42: 117700 | E42: 8688 | F42: 187800 | G42: 0.00205 | H42: 1|4 | I42: 398.5 | J42: 233.4 | K42: 114100 | L42: 6295 | M42: 36370 | N42: 0.002043 | O42: 1|4 | P42: 329.6 | Q42: 151.5 | R42: 74180 | S42: 3398 | T42: 11820 | U42: 0.002041 | V42: 1|4 | W42: 213 | X42: 188.2 | Y42: 92130 | Z42: 5358 | AA42: 2937 | AB42: 0.002039 | AC42: 1|4 | AD42: 178.4 | AE42: 182.6 | AF42: 90610 | AG42: 1735 | AH42: 1442 | AI42: 0.002015 | AJ42: 1|4 | AK42: 160.4 | AL42: 213.5 | AM42: 104500 | AN42: 7430 | AO42: 833.5 | AP42: 0.002038 | AQ42: 1|4 | AR42: 155 | AS42: 215.6 | AT42: 104500 | AU42: 8101 | AV42: 544.1 | AW42: 0.002057 | AX42: 1|4 | AY42: 148.8 | AZ42: 207.6 | BA42: 99890 | BB42: 9715 | BC42: 312.6 | BD42: 0.002069 | BE42: 1|4 | BF42: 148.1 | BG42: 197 | BH42: 95150 | BI42: 10820 | BJ42: 203.2 | BK42: 0.002057 | BL42: 1|4 | BM42: 146.2 | BN42: 139.2 | BO42: 67260 | BP42: 12220 | BQ42: 108.8 | BR42: 0.002036
A43: 1|5 | B43: 1197 | C43: 304.4 | D43: 117000 | E43: 8935 | F43: 186800 | G43: 0.002594 | H43: 1|5 | I43: 500.5 | J43: 291.8 | K43: 112100 | L43: 6618 | M43: 35740 | N43: 0.002599 | O43: 1|5 | P43: 414.4 | Q43: 191.4 | R43: 73560 | S43: 3779 | T43: 11720 | U43: 0.002598 | V43: 1|5 | W43: 268.5 | X43: 238.2 | Y43: 91420 | Z43: 5655 | AA43: 2916 | AB43: 0.002601 | AC43: 1|5 | AD43: 226.6 | AE43: 239.8 | AF43: 92750 | AG43: 4867 | AH43: 1478 | AI43: 0.002581 | AJ43: 1|5 | AK43: 202.3 | AL43: 270.6 | AM43: 103900 | AN43: 6753 | AO43: 828.9 | AP43: 0.002598 | AQ43: 1|5 | AR43: 195.9 | AS43: 268.8 | AT43: 104000 | AU43: 7348 | AV43: 541.4 | AW43: 0.002577 | AX43: 1|5 | AY43: 188.6 | AZ43: 259.7 | BA43: 100700 | BB43: 9222 | BC43: 314.9 | BD43: 0.002568 | BE43: 1|5 | BF43: 187.2 | BG43: 240.5 | BH43: 92500 | BI43: 10470 | BJ43: 197.5 | BK43: 0.002583 | BL43: 1|5 | BM43: 184.4 | BN43: 174.9 | BO43: 79560 | BP43: 10190 | BQ43: 127.7 | BR43: 0.00218
...

Sheet output_data
B1: f | C1: Gamma_0v | D1: G'_0v | E1: Gamma_500v | F1: G'_500v | G1: Gamma_1000v | H1: G'_1000v | I1: Gamma_Katal68=3p_500v | J1: G'_Katal68=3p_500v | K1: Gamma_Katal68=3p_1000v | L1: G'_Katal68=3p_1000v | O1: ---------- | P1: Gamma_0v | Q1: G''_0v | R1: Gamma_500v | S1: G''_500v | T1: Gamma_1000v | U1: G''_1000v | V1: Gamma_Katal68=3p_500v | W1: G''_Katal68=3p_500v | X1: Gamma_Katal68=3p_1000v | Y1: G''_Katal68=3p_1000v | AB1: ---------- | AC1: Gamma_0v | AD1: |Eta*|_0v | AE1: Gamma_500v | AF1: |Eta*|_500v | AG1: Gamma_1000v | AH1: |Eta*|_1000v | AI1: Gamma_Katal68=3p_500v | AJ1: |Eta*|_Katal68=3p_500v | AK1: Gamma_Katal68=3p_1000v | AL1: |Eta*|_Katal68=3p_1000v | AO1: ---------- | AP1: Tau_0v | AQ1: Tau_500v | AR1: Tau_1000v | AS1: Tau_Katal68=3p_500v | AT1: Tau_Katal68=3p_1000v | AV1: ---------- | AW1: G'_0v | AX1: G''_0v | AY1: tan_δ_0v | AZ1: G'_500v | BA1: G''_500v | BB1: tan_δ_500v | BC1: G'_1000v | BD1: G''_1000v | BE1: tan_δ_1000v | BF1: G'_Katal68=3p_500v | BG1: G''_Katal68=3p_500v | BH1: tan_δ_Katal68=3p_500v | BI1: G'_Katal68=3p_1000v | BJ1: G''_Katal68=3p_1000v | BK1: tan_δ_Katal68=3p_1000v | BO1: ---------- | BP1: tan_δ_0v | BQ1: tan_δ_500v | BR1: tan_δ_1000v | BS1: tan_δ_Katal68=3p_500v | BT1: tan_δ_Katal68=3p_1000v | BV1: ----------
B2: Hz | D2: Pa | F2: Pa | H2: Pa | J2: Pa | L2: Pa | N2: Pa | Q2: Pa | S2: Pa | U2: Pa | W2: Pa | Y2: Pa | AA2: Pa | AD2: Pas | AF2: Pas | AH2: Pas | AJ2: Pas | AL2: Pas | AN2: Pas | AP2: Pa | AQ2: Pa | AR2: Pa | AS2: Pa | AT2: Pa | AU2: Pa | AW2: Pa | AX2: Pa | AZ2: Pa | BA2: Pa | BC2: Pa | BD2: Pa | BF2: Pa | BG2: Pa | BI2: Pa | BJ2: Pa | BL2: Pa | BM2: Pa
C3: SCTNA=60p_Katal68=2p_PyrO=40p_0v | D3: SCTNA=60p_Katal68=2p_PyrO=40p_0v | E3: SCTNA=60p_Katal68=2p_PyrO=40p_500v | F3: SCTNA=60p_Katal68=2p_PyrO=40p_500v | G3: SCTNA=60p_Katal68=2p_PyrO=40p_1000v | H3: SCTNA=60p_Katal68=2p_PyrO=40p_1000v | I3: SCTNA=60p_Katal68=3p_PyrO=40p_500v | J3: SCTNA=60p_Katal68=3p_PyrO=40p_500v | K3: SCTNA=60p_Katal68=3p_PyrO=40p_1000v | L3: SCTNA=60p_Katal68=3p_PyrO=40p_1000v | P3: SCTNA=60p_Katal68=2p_PyrO=40p_0v | Q3: SCTNA=60p_Katal68=2p_PyrO=40p_0v | R3: SCTNA=60p_Katal68=2p_PyrO=40p_500v | S3: SCTNA=60p_Katal68=2p_PyrO=40p_500v | T3: SCTNA=60p_Katal68=2p_PyrO=40p_1000v | U3: SCTNA=60p_Katal68=2p_PyrO=40p_1000v | V3: SCTNA=60p_Katal68=3p_PyrO=40p_500v | W3: SCTNA=60p_Katal68=3p_PyrO=40p_500v | X3: SCTNA=60p_Katal68=3p_PyrO=40p_1000v | Y3: SCTNA=60p_Katal68=3p_PyrO=40p_1000v | AC3: SCTNA=60p_Katal68=2p_PyrO=40p_0v | AD3: SCTNA=60p_Katal68=2p_PyrO=40p_0v | AE3: SCTNA=60p_Katal68=2p_PyrO=40p_500v | AF3: SCTNA=60p_Katal68=2p_PyrO=40p_500v | AG3: SCTNA=60p_Katal68=2p_PyrO=40p_1000v | AH3: SCTNA=60p_Katal68=2p_PyrO=40p_1000v | AI3: SCTNA=60p_Katal68=3p_PyrO=40p_500v | AJ3: SCTNA=60p_Katal68=3p_PyrO=40p_500v | AK3: SCTNA=60p_Katal68=3p_PyrO=40p_1000v | AL3: SCTNA=60p_Katal68=3p_PyrO=40p_1000v | AP3: SCTNA=60p_Katal68=2p_PyrO=40p_0v | AQ3: SCTNA=60p_Katal68=2p_PyrO=40p_500v | AR3: SCTNA=60p_Katal68=2p_PyrO=40p_1000v | AS3: SCTNA=60p_Katal68=3p_PyrO=40p_500v | AT3: SCTNA=60p_Katal68=3p_PyrO=40p_1000v | AW3: SCTNA=60p_Katal68=2p_PyrO=40p_0v | AX3: SCTNA=60p_Katal68=2p_PyrO=40p_0v | AY3: SCTNA=60p_Katal68=2p_PyrO=40p_0v | AZ3: SCTNA=60p_Katal68=2p_PyrO=40p_500v | BA3: SCTNA=60p_Katal68=2p_PyrO=40p_500v | BB3: SCTNA=60p_Katal68=2p_PyrO=40p_500v | BC3: SCTNA=60p_Katal68=2p_PyrO=40p_1000v | BD3: SCTNA=60p_Katal68=2p_PyrO=40p_1000v | BE3: SCTNA=60p_Katal68=2p_PyrO=40p_1000v | BF3: SCTNA=60p_Katal68=3p_PyrO=40p_500v | BG3: SCTNA=60p_Katal68=3p_PyrO=40p_500v | BH3: SCTNA=60p_Katal68=3p_PyrO=40p_500v | BI3: SCTNA=60p_Katal68=3p_PyrO=40p_1000v | BJ3: SCTNA=60p_Katal68=3p_PyrO=40p_1000v | BK3: SCTNA=60p_Katal68=3p_PyrO=40p_1000v | BP3: SCTNA=60p_Katal68=2p_PyrO=40p_0v | BQ3: SCTNA=60p_Katal68=2p_PyrO=40p_500v | BR3: SCTNA=60p_Katal68=2p_PyrO=40p_1000v | BS3: SCTNA=60p_Katal68=3p_PyrO=40p_500v | BT3: SCTNA=60p_Katal68=3p_PyrO=40p_1000v
A4: Частота 0,1 Гц | O4: Частота 0,1 Гц | AB4: Частота 0,1 Гц | AV4: Частота 0,1 Гц | BO4: Частота 0,1 Гц
A5: 1 | B5: 0.1 | C5: =IF(input_data!G4="","",input_data!G4) -> 0.01161 | D5: =IF(input_data!D4="","",input_data!D4) -> 121400 | E5: =IF(input_data!G39="","",input_data!G39) -> 0.001026 | F5: =IF(input_data!D39="","",input_data!D39) -> 118400 | G5: =IF(input_data!G73="","",input_data!G73) -> 0.0009908 | H5: =IF(input_data!D73="","",input_data!D73) -> 105000 | I5: =IF(input_data!G107="","",input_data!G107) | J5: =IF(input_data!D107="","",input_data!D107) | K5: =IF(input_data!G141="","",input_data!G141) | L5: =IF(input_data!D141="","",input_data!D141) | M5: =IF(input_data!G175="","",input_data!G175) | N5: =IF(input_data!D175="","",input_data!D175) | O5: ---------- | P5: =IF(input_data!G4="","",input_data!G4) -> 0.01161 | Q5: =IF(input_data!E4="","",input_data!E4) -> 34680 | R5: =IF(input_data!G39="","",input_data!G39) -> 0.001026 | S5: =IF(input_data!E39="","",input_data!E39) -> 8430 | T5: =IF(input_data!G73="","",input_data!G73) -> 0.0009908 | U5: =IF(input_data!E73="","",input_data!E73) -> 9161 | V5: =IF(input_data!G107="","",input_data!G107) | W5: =IF(input_data!E107="","",input_data!E107) | X5: =IF(input_data!G141="","",input_data!G141) | Y5: =IF(input_data!E141="","",input_data!E141) | Z5: =IF(input_data!G175="","",input_data!G175) | AA5: =IF(input_data!E175="","",input_data!E175) | AC5: =IF(input_data!G4="","",input_data!G4) -> 0.01161 | AD5: =IF(input_data!F4="","",input_data!F4) -> 200900 | AE5: =IF(input_data!G39="","",input_data!G39) -> 0.001026 | AF5: =IF(input_data!F39="","",input_data!F39) -> 189000 | AG5: =IF(input_data!G73="","",input_data!G73) -> 0.0009908 | AH5: =IF(input_data!F73="","",input_data!F73) -> 167800 | AI5: =IF(input_data!G107="","",input_data!G107) | AJ5: =IF(input_data!F107="","",input_data!F107) | AK5: =IF(input_data!G141="","",input_data!G141) | AL5: =IF(input_data!F141="","",input_data!F141) | AM5: =IF(input_data!G175="","",input_data!G175) | AN5: =IF(input_data!F175="","",input_data!F175) | AP5: =IF(input_data!C4="","",input_data!C4) -> 1466 | AQ5: =IF(input_data!C39="","",input_data!C39) -> 121.9 | AR5: =IF(input_data!C73="","",input_data!C73) -> 104.4 | AS5: =IF(input_data!C107="","",input_data!C107) | AT5: =IF(input_data!C141="","",input_data!C141) | AU5: =IF(input_data!C175="","",input_data!C175) | AW5: =IF(input_data!D4="","",input_data!D4) -> 121400 | AX5: =IF(input_data!E4="","",input_data!E4) -> 34680 | AY5: =IFERROR(IF(OR(AW5="",AX5=""),"",AX5/AW5),"") -> 0.28566722 | AZ5: =IF(input_data!D39="","",input_data!D39) -> 118400 | BA5: =IF(input_data!E39="","",input_data!E39) -> 8430 | BB5: =IFERROR(IF(OR(AZ5="",BA5=""),"",BA5/AZ5),"") -> 0.071199324 | BC5: =IF(input_data!D73="","",input_data!D73) -> 105000 | BD5: =IF(input_data!E73="","",input_data!E73) -> 9161 | BE5: =IFERROR(IF(OR(BC5="",BD5=""),"",BD5/BC5),"") -> 0.087247619 | BF5: =IF(input_data!D107="","",input_data!D107) | BG5: =IF(input_data!E107="","",input_data!E107) | BH5: =IFERROR(IF(OR(BF5="",BG5=""),"",BG5/BF5),"") | BI5: =IF(input_data!D141="","",input_data!D141) | BJ5: =IF(input_data!E141="","",input_data!E141) | BK5: =IFERROR(IF(OR(BI5="",BJ5=""),"",BJ5/BI5),"") | BL5: =IF(input_data!D175="","",input_data!D175) | BM5: =IF(input_data!E175="","",input_data!E175) | BN5: =IFERROR(IF(OR(BL5="",BM5=""),"",BM5/BL5),"") | BP5: =AY5 -> 0.28566722 | BQ5: =BB5 -> 0.071199324 | BR5: =BE5 -> 0.087247619 | BS5: =BH5 | BT5: =BK5 | BU5: =BN5 | BV5: ----------
A6: 2 | B6: 0.1 | C6: =IF(input_data!G5="","",input_data!G5) -> 0.01363 | D6: =IF(input_data!D5="","",input_data!D5) -> 119900 | E6: =IF(input_data!G40="","",input_data!G40) -> 0.001268 | F6: =IF(input_data!D40="","",input_data!D40) -> 119300 | G6: =IF(input_data!G74="","",input_data!G74) -> 0.001263 | H6: =IF(input_data!D74="","",input_data!D74) -> 111200 | I6: =IF(input_data!G108="","",input_data!G108) | J6: =IF(input_data!D108="","",input_data!D108) | K6: =IF(input_data!G142="","",input_data!G142) | L6: =IF(input_data!D142="","",input_data!D142) | M6: =IF(input_data!G176="","",input_data!G176) | N6: =IF(input_data!D176="","",input_data!D176) | O6: ---------- | P6: =IF(input_data!G5="","",input_data!G5) -> 0.01363 | Q6: =IF(input_data!E5="","",input_data!E5) -> 35400 | R6: =IF(input_data!G40="","",input_data!G40) -> 0.001268 | S6: =IF(input_data!E40="","",input_data!E40) -> 8262 | T6: =IF(input_data!G74="","",input_data!G74) -> 0.001263 | U6: =IF(input_data!E74="","",input_data!E74) -> 9316 | V6: =IF(input_data!G108="","",input_data!G108) | W6: =IF(input_data!E108="","",input_data!E108) | X6: =IF(input_data!G142="","",input_data!G142) | Y6: =IF(input_data!E142="","",input_data!E142) | Z6: =IF(input_data!G176="","",input_data!G176) | AA6: =IF(input_data!E176="","",input_data!E176) | AC6: =IF(input_data!G5="","",input_data!G5) -> 0.01363 | AD6: =IF(input_data!F5="","",input_data!F5) -> 198900 | AE6: =IF(input_data!G40="","",input_data!G40) -> 0.001268 | AF6: =IF(input_data!F40="","",input_data!F40) -> 190300 | AG6: =IF(input_data!G74="","",input_data!G74) -> 0.001263 | AH6: =IF(input_data!F74="","",input_data!F74) -> 177500 | AI6: =IF(input_data!G108="","",input_data!G108) | AJ6: =IF(input_data!F108="","",input_data!F108) | AK6: =IF(input_data!G142="","",input_data!G142) | AL6: =IF(input_data!F142="","",input_data!F142) | AM6: =IF(input_data!G176="","",input_data!G176) | AN6: =IF(input_data!F176="","",input_data!F176) | AP6: =IF(input_data!C5="","",input_data!C5) -> 1704 | AQ6: =IF(input_data!C40="","",input_data!C40) -> 151.6 | AR6: =IF(input_data!C74="","",input_data!C74) -> 140.9 | AS6: =IF(input_data!C108="","",input_data!C108) | AT6: =IF(input_data!C142="","",input_data!C142) | AU6: =IF(input_data!C176="","",input_data!C176) | AW6: =IF(input_data!D5="","",input_data!D5) -> 119900 | AX6: =IF(input_data!E5="","",input_data!E5) -> 35400 | AY6: =IFERROR(IF(OR(AW6="",AX6=""),"",AX6/AW6),"") -> 0.29524604 | AZ6: =IF(input_data!D40="","",input_data!D40) -> 119300 | BA6: =IF(input_data!E40="","",input_data!E40) -> 8262 | BB6: =IFERROR(IF(OR(AZ6="",BA6=""),"",BA6/AZ6),"") -> 0.069253982 | BC6: =IF(input_data!D74="","",input_data!D74) -> 111200 | BD6: =IF(input_data!E74="","",input_data!E74) -> 9316 | BE6: =IFERROR(IF(OR(BC6="",BD6=""),"",BD6/BC6),"") -> 0.083776978 | BF6: =IF(input_data!D108="","",input_data!D108) | BG6: =IF(input_data!E108="","",input_data!E108) | BH6: =IFERROR(IF(OR(BF6="",BG6=""),"",BG6/BF6),"") | BI6: =IF(input_data!D142="","",input_data!D142) | BJ6: =IF(input_data!E142="","",input_data!E142) | BK6: =IFERROR(IF(OR(BI6="",BJ6=""),"",BJ6/BI6),"") | BL6: =IF(input_data!D176="","",input_data!D176) | BM6: =IF(input_data!E176="","",input_data!E176) | BN6: =IFERROR(IF(OR(BL6="",BM6=""),"",BM6/BL6),"") | BP6: =AY6 -> 0.29524604 | BQ6: =BB6 -> 0.069253982 | BR6: =BE6 -> 0.083776978 | BS6: =BH6 | BT6: =BK6 | BU6: =BN6 | BV6: ----------
A7: 3 | B7: 0.1 | C7: =IF(input_data!G6="","",input_data!G6) -> 0.01866 | D7: =IF(input_data!D6="","",input_data!D6) -> 104300 | E7: =IF(input_data!G41="","",input_data!G41) -> 0.001622 | F7: =IF(input_data!D41="","",input_data!D41) -> 117900 | G7: =IF(input_data!G75="","",input_data!G75) -> 0.001609 | H7: =IF(input_data!D75="","",input_data!D75) -> 112100 | I7: =IF(input_data!G109="","",input_data!G109) | J7: =IF(input_data!D109="","",input_data!D109) | K7: =IF(input_data!G143="","",input_data!G143) | L7: =IF(input_data!D143="","",input_data!D143) | M7: =IF(input_data!G177="","",input_data!G177) | N7: =IF(input_data!D177="","",input_data!D177) | O7: ---------- | P7: =IF(input_data!G6="","",input_data!G6) -> 0.01866 | Q7: =IF(input_data!E6="","",input_data!E6) -> 36350 | R7: =IF(input_data!G41="","",input_data!G41) -> 0.001622 | S7: =IF(input_data!E41="","",input_data!E41) -> 6455 | T7: =IF(input_data!G75="","",input_data!G75) -> 0.001609 | U7: =IF(input_data!E75="","",input_data!E75) -> 9493 | V7: =IF(input_data!G109="","",input_data!G109) | W7: =IF(input_data!E109="","",input_data!E109) | X7: =IF(input_data!G143="","",input_data!G143) | Y7: =IF(input_data!E143="","",input_data!E143) | Z7: =IF(input_data!G177="","",input_data!G177) | AA7: =IF(input_data!E177="","",input_data!E177) | AC7: =IF(input_data!G6="","",input_data!G6) -> 0.01866 | AD7: =IF(input_data!F6="","",input_data!F6) -> 175900 | AE7: =IF(input_data!G41="","",input_data!G41) -> 0.001622 | AF7: =IF(input_data!F41="","",input_data!F41) -> 187900 | AG7: =IF(input_data!G75="","",input_data!G75) -> 0.001609 | AH7: =IF(input_data!F75="","",input_data!F75) -> 179000 | AI7: =IF(input_data!G109="","",input_data!G109) | AJ7: =IF(input_data!F109="","",input_data!F109) | AK7: =IF(input_data!G143="","",input_data!G143) | AL7: =IF(input_data!F143="","",input_data!F143) | AM7: =IF(input_data!G177="","",input_data!G177) | AN7: =IF(input_data!F177="","",input_data!F177) | AP7: =IF(input_data!C6="","",input_data!C6) -> 2062 | AQ7: =IF(input_data!C41="","",input_data!C41) -> 191.4 | AR7: =IF(input_data!C75="","",input_data!C75) -> 181 | AS7: =IF(input_data!C109="","",input_data!C109) | AT7: =IF(input_data!C143="","",input_data!C143) | AU7: =IF(input_data!C177="","",input_data!C177) | AW7: =IF(input_data!D6="","",input_data!D6) -> 104300 | AX7: =IF(input_data!E6="","",input_data!E6) -> 36350 | AY7: =IFERROR(IF(OR(AW7="",AX7=""),"",AX7/AW7),"") -> 0.3485139 | AZ7: =IF(input_data!D41="","",input_data!D41) -> 117900 | BA7: =IF(input_data!E41="","",input_data!E41) -> 6455 | BB7: =IFERROR(IF(OR(AZ7="",BA7=""),"",BA7/AZ7),"") -> 0.054749788 | BC7: =IF(input_data!D75="","",input_data!D75) -> 112100 | BD7: =IF(input_data!E75="","",input_data!E75) -> 9493 | BE7: =IFERROR(IF(OR(BC7="",BD7=""),"",BD7/BC7),"") -> 0.084683318 | BF7: =IF(input_data!D109="","",input_data!D109) | BG7: =IF(input_data!E109="","",input_data!E109) | BH7: =IFERROR(IF(OR(BF7="",BG7=""),"",BG7/BF7),"") | BI7: =IF(input_data!D143="","",input_data!D143) | BJ7: =IF(input_data!E143="","",input_data!E143) | BK7: =IFERROR(IF(OR(BI7="",BJ7=""),"",BJ7/BI7),"") | BL7: =IF(input_data!D177="","",input_data!D177) | BM7: =IF(input_data!E177="","",input_data!E177) | BN7: =IFERROR(IF(OR(BL7="",BM7=""),"",BM7/BL7),"") | BP7: =AY7 -> 0.3485139 | BQ7: =BB7 -> 0.054749788 | BR7: =BE7 -> 0.084683318 | BS7: =BH7 | BT7: =BK7 | BU7: =BN7 | BV7: ----------
A8: 4 | B8: 0.1 | C8: =IF(input_data!G7="","",input_data!G7) -> 0.02513 | D8: =IF(input_data!D7="","",input_data!D7) -> 89100 | E8: =IF(input_data!G42="","",input_data!G42) -> 0.00205 | F8: =IF(input_data!D42="","",input_data!D42) -> 117700 | G8: =IF(input_data!G76="","",input_data!G76) -> 0.002047 | H8: =IF(input_data!D76="","",input_data!D76) -> 111800 | I8: =IF(input_data!G110="","",input_data!G110) | J8: =IF(input_data!D110="","",input_data!D110) | K8: =IF(input_data!G144="","",input_data!G144) | L8: =IF(input_data!D144="","",input_data!D144) | M8: =IF(input_data!G178="","",input_data!G178) | N8: =IF(input_data!D178="","",input_data!D178) | O8: ---------- | P8: =IF(input_data!G7="","",input_data!G7) -> 0.02513 | Q8: =IF(input_data!E7="","",input_data!E7) -> 36010 | R8: =IF(input_data!G42="","",input_data!G42) -> 0.00205 | S8: =IF(input_data!E42="","",input_data!E42) -> 8688 | T8: =IF(input_data!G76="","",input_data!G76) -> 0.002047 | U8: =IF(input_data!E76="","",input_data!E76) -> 9758 | V8: =IF(input_data!G110="","",input_data!G110) | W8: =IF(input_data!E110="","",input_data!E110) | X8: =IF(input_data!G144="","",input_data!G144) | Y8: =IF(input_data!E144="","",input_data!E144) | Z8: =IF(input_data!G178="","",input_data!G178) | AA8: =IF(input_data!E178="","",input_data!E178) | AC8: =IF(input_data!G7="","",input_data!G7) -> 0.02513 | AD8: =IF(input_data!F7="","",input_data!F7) -> 152900 | AE8: =IF(input_data!G42="","",input_data!G42) -> 0.00205 | AF8: =IF(input_data!F42="","",input_data!F42) -> 187800 | AG8: =IF(input_data!G76="","",input_data!G76) -> 0.002047 | AH8: =IF(input_data!F76="","",input_data!F76) -> 178600 | AI8: =IF(input_data!G110="","",input_data!G110) | AJ8: =IF(input_data!F110="","",input_data!F110) | AK8: =IF(input_data!G144="","",input_data!G144) | AL8: =IF(input_data!F144="","",input_data!F144) | AM8: =IF(input_data!G178="","",input_data!G178) | AN8: =IF(input_data!F178="","",input_data!F178) | AP8: =IF(input_data!C7="","",input_data!C7) -> 2415 | AQ8: =IF(input_data!C42="","",input_data!C42) -> 241.9 | AR8: =IF(input_data!C76="","",input_data!C76) -> 229.7 | AS8: =IF(input_data!C110="","",input_data!C110) | AT8: =IF(input_data!C144="","",input_data!C144) | AU8: =IF(input_data!C178="","",input_data!C178) | AW8: =IF(input_data!D7="","",input_data!D7) -> 89100 | AX8: =IF(input_data!E7="","",input_data!E7) -> 36010 | AY8: =IFERROR(IF(OR(AW8="",AX8=""),"",AX8/AW8),"") -> 0.40415264 | AZ8: =IF(input_data!D42="","",input_data!D42) -> 117700 | BA8: =IF(input_data!E42="","",input_data!E42) -> 8688 | BB8: =IFERROR(IF(OR(AZ8="",BA8=""),"",BA8/AZ8),"") -> 0.073814783 | BC8: =IF(input_data!D76="","",input_data!D76) -> 111800 | BD8: =IF(input_data!E76="","",input_data!E76) -> 9758 | BE8: =IFERROR(IF(OR(BC8="",BD8=""),"",BD8/BC8),"") -> 0.087280859 | BF8: =IF(input_data!D110="","",input_data!D110) | BG8: =IF(input_data!E110="","",input_data!E110) | BH8: =IFERROR(IF(OR(BF8="",BG8=""),"",BG8/BF8),"") | BI8: =IF(input_data!D144="","",input_data!D144) | BJ8: =IF(input_data!E144="","",input_data!E144) | BK8: =IFERROR(IF(OR(BI8="",BJ8=""),"",BJ8/BI8),"") | BL8: =IF(input_data!D178="","",input_data!D178) | BM8: =IF(input_data!E178="","",input_data!E178) | BN8: =IFERROR(IF(OR(BL8="",BM8=""),"",BM8/BL8),"") | BP8: =AY8 -> 0.40415264 | BQ8: =BB8 -> 0.073814783 | BR8: =BE8 -> 0.087280859 | BS8: =BH8 | BT8: =BK8 | BU8: =BN8 | BV8: ----------
A9: 5 | B9: 0.1 | C9: =IF(input_data!G8="","",input_data!G8) -> 0.03473 | D9: =IF(input_data!D8="","",input_data!D8) -> 74140 | E9: =IF(input_data!G43="","",input_data!G43) -> 0.002594 | F9: =IF(input_data!D43="","",input_data!D43) -> 117000 | G9: =IF(input_data!G77="","",input_data!G77) -> 0.00259 | H9: =IF(input_data!D77="","",input_data!D77) -> 110400 | I9: =IF(input_data!G111="","",input_data!G111) | J9: =IF(input_data!D111="","",input_data!D111) | K9: =IF(input_data!G145="","",input_data!G145) | L9: =IF(input_data!D145="","",input_data!D145) | M9: =IF(input_data!G179="","",input_data!G179) | N9: =IF(input_data!D179="","",input_data!D179) | O9: ---------- | P9: =IF(input_data!G8="","",input_data!G8) -> 0.03473 | Q9: =IF(input_data!E8="","",input_data!E8) -> 33790 | R9: =IF(input_data!G43="","",input_data!G43) -> 0.002594 | S9: =IF(input_data!E43="","",input_data!E43) -> 8935 | T9: =IF(input_data!G77="","",input_data!G77) -> 0.00259 | U9: =IF(input_data!E77="","",input_data!E77) -> 9918 | V9: =IF(input_data!G111="","",input_data!G111) | W9: =IF(input_data!E111="","",input_data!E111) | X9: =IF(input_data!G145="","",input_data!G145) | Y9: =IF(input_data!E145="","",input_data!E145) | Z9: =IF(input_data!G179="","",input_data!G179) | AA9: =IF(input_data!E179="","",input_data!E179) | AC9: =IF(input_data!G8="","",input_data!G8) -> 0.03473 | AD9: =IF(input_data!F8="","",input_data!F8) -> 129700 | AE9: =IF(input_data!G43="","",input_data!G43) -> 0.002594 | AF9: =IF(input_data!F43="","",input_data!F43) -> 186800 | AG9: =IF(input_data!G77="","",input_data!G77) -> 0.00259 | AH9: =IF(input_data!F77="","",input_data!F77) -> 176400 | AI9: =IF(input_data!G111="","",input_data!G111) | AJ9: =IF(input_data!F111="","",input_data!F111) | AK9: =IF(input_data!G145="","",input_data!G145) | AL9: =IF(input_data!F145="","",input_data!F145) | AM9: =IF(input_data!G179="","",input_data!G179) | AN9: =IF(input_data!F179="","",input_data!F179) | AP9: =IF(input_data!C8="","",input_data!C8) -> 2829 | AQ9: =IF(input_data!C43="","",input_data!C43) -> 304.4 | AR9: =IF(input_data!C77="","",input_data!C77) -> 287.2 | AS9: =IF(input_data!C111="","",input_data!C111) | AT9: =IF(input_data!C145="","",input_data!C145) | AU9: =IF(input_data!C179="","",input_data!C179) | AW9: =IF(input_data!D8="","",input_data!D8) -> 74140 | AX9: =IF(input_data!E8="","",input_data!E8) -> 33790 | AY9: =IFERROR(IF(OR(AW9="",AX9=""),"",AX9/AW9),"") -> 0.45575937 | AZ9: =IF(input_data!D43="","",input_data!D43) -> 117000 | BA9: =IF(input_data!E43="","",input_data!E43) -> 8935 | BB9: =IFERROR(IF(OR(AZ9="",BA9=""),"",BA9/AZ9),"") -> 0.076367521 | BC9: =IF(input_data!D77="","",input_data!D77) -> 110400 | BD9: =IF(input_data!E77="","",input_data!E77) -> 9918 | BE9: =IFERROR(IF(OR(BC9="",BD9=""),"",BD9/BC9),"") -> 0.089836957 | BF9: =IF(input_data!D111="","",input_data!D111) | BG9: =IF(input_data!E111="","",input_data!E111) | BH9: =IFERROR(IF(OR(BF9="",BG9=""),"",BG9/BF9),"") | BI9: =IF(input_data!D145="","",input_data!D145) | BJ9: =IF(input_data!E145="","",input_data!E145) | BK9: =IFERROR(IF(OR(BI9="",BJ9=""),"",BJ9/BI9),"") | BL9: =IF(input_data!D179="","",input_data!D179) | BM9: =IF(input_data!E179="","",input_data!E179) | BN9: =IFERROR(IF(OR(BL9="",BM9=""),"",BM9/BL9),"") | BP9: =AY9 -> 0.45575937 | BQ9: =BB9 -> 0.076367521 | BR9: =BE9 -> 0.089836957 | BS9: =BH9 | BT9: =BK9 | BU9: =BN9 | BV9: ----------
A10: 6 | B10: 0.1 | C10: =IF(input_data!G9="","",input_data!G9) -> 0.04684 | D10: =IF(input_data!D9="","",input_data!D9) -> 62630 | E10: =IF(input_data!G44="","",input_data!G44) -> 0.003292 | F10: =IF(input_data!D44="","",input_data!D44) -> 115300 | G10: =IF(input_data!G78="","",input_data!G78) -> 0.003288 | H10: =IF(input_data!D78="","",input_data!D78) -> 107200 | I10: =IF(input_data!G112="","",input_data!G112) | J10: =IF(input_data!D112="","",input_data!D112) | K10: =IF(input_data!G146="","",input_data!G146) | L10: =IF(input_data!D146="","",input_data!D146) | M10: =IF(input_data!G180="","",input_data!G180) | N10: =IF(input_data!D180="","",input_data!D180) | O10: ---------- | P10: =IF(input_data!G9="","",input_data!G9) -> 0.04684 | Q10: =IF(input_data!E9="","",input_data!E9) -> 31160 | R10: =IF(input_data!G44="","",input_data!G44) -> 0.003292 | S10: =IF(input_data!E44="","",input_data!E44) -> 9489 | T10: =IF(input_data!G78="","",input_data!G78) -> 0.003288 | U10: =IF(input_data!E78="","",input_data!E78) -> 10010 | V10: =IF(input_data!G112="","",input_data!G112) | W10: =IF(input_data!E112="","",input_data!E112) | X10: =IF(input_data!G146="","",input_data!G146) | Y10: =IF(input_data!E146="","",input_data!E146) | Z10: =IF(input_data!G180="","",input_data!G180) | AA10: =IF(input_data!E180="","",input_data!E180) | AC10: =IF(input_data!G9="","",input_data!G9) -> 0.04684 | AD10: =IF(input_data!F9="","",input_data!F9) -> 111300 | AE10: =IF(input_data!G44="","",input_data!G44) -> 0.003292 | AF10: =IF(input_data!F44="","",input_data!F44) -> 184100 | AG10: =IF(input_data!G78="","",input_data!G78) -> 0.003288 | AH10: =IF(input_data!F78="","",input_data!F78) -> 171300 | AI10: =IF(input_data!G112="","",input_data!G112) | AJ10: =IF(input_data!F112="","",input_data!F112) | AK10: =IF(input_data!G146="","",input_data!G146) | AL10: =IF(input_data!F146="","",input_data!F146) | AM10: =IF(input_data!G180="","",input_data!G180) | AN10: =IF(input_data!F180="","",input_data!F180) | AP10: =IF(input_data!C9="","",input_data!C9) -> 3277 | AQ10: =IF(input_data!C44="","",input_data!C44) -> 380.7 | AR10: =IF(input_data!C78="","",input_data!C78) -> 353.9 | AS10: =IF(input_data!C112="","",input_data!C112) | AT10: =IF(input_data!C146="","",input_data!C146) | AU10: =IF(input_data!C180="","",input_data!C180) | AW10: =IF(input_data!D9="","",input_data!D9) -> 62630 | AX10: =IF(input_data!E9="","",input_data!E9) -> 31160 | AY10: =IFERROR(IF(OR(AW10="",AX10=""),"",AX10/AW10),"") -> 0.49752515 | AZ10: =IF(input_data!D44="","",input_data!D44) -> 115300 | BA10: =IF(input_data!E44="","",input_data!E44) -> 9489 | BB10: =IFERROR(IF(OR(AZ10="",BA10=""),"",BA10/AZ10),"") -> 0.082298352 | BC10: =IF(input_data!D78="","",input_data!D78) -> 107200 | BD10: =IF(input_data!E78="","",input_data!E78) -> 10010 | BE10: =IFERROR(IF(OR(BC10="",BD10=""),"",BD10/BC10),"") -> 0.093376866 | BF10: =IF(input_data!D112="","",input_data!D112) | BG10: =IF(input_data!E112="","",input_data!E112) | BH10: =IFERROR(IF(OR(BF10="",BG10=""),"",BG10/BF10),"") | BI10: =IF(input_data!D146="","",input_data!D146) | BJ10: =IF(input_data!E146="","",input_data!E146) | BK10: =IFERROR(IF(OR(BI10="",BJ10=""),"",BJ10/BI10),"") | BL10: =IF(input_data!D180="","",input_data!D180) | BM10: =IF(input_data!E180="","",input_data!E180) | BN10: =IFERROR(IF(OR(BL10="",BM10=""),"",BM10/BL10),"") | BP10: =AY10 -> 0.49752515 | BQ10: =BB10 -> 0.082298352 | BR10: =BE10 -> 0.093376866 | BS10: =BH10 | BT10: =BK10 | BU10: =BN10 | BV10: ----------
